Workbook

Sheet Required changes checklist
A1: Change ID | B1: Name | C1: Description | D1: Done Date | E1: Notes
A2: 0 | B2: Change the file location | C2: Currently the master file is not in a secure location. Only a copy should be shared in the weely deck file. master should be kept in a separate location with limited access to just mobile marketing. | E2: Do you mean we need to keep the collated file in PPT Automated folder?
A3: 0A | B3: Several versions and tables of collated file exist. Need to decide on best way to collate.
A4: 1 | B4: Clean up data set formatting: | C4: Unhide all columns, and clean up, be careful not to remove old data that might be useful. Remove Blank rows, columns and move data around so newest row is at the very bottom of the sheet | E4: There will some columns which will be blank for recent times as the inputs for those column are not available for present times. For e.g. installs from Tapjoy / Liftoff etc
A5: 2 | B5: Remove Blank Rows and Columns | C5: Remove rows that are blank and columns, remove extra column titles. This will allow for easier utilization of the excel file.
A6: 3 | B6: Re-order data to decending order (newest week is at the bottom of the sheet) | I6: Wide to long format is "Ideal" however, LOE may not be worth the benefit. But note there are many benefits from this format.
A7: 5 | B7: Newest week should be added to the bottom of the sheet.
A8: 6 | B8: Some data will need to be on secondary tables, this data should deffinitely follow tidy data principles. (other strategies for data base design could also be implemented here. I'm open to ideas. But in the end, the data should be easily put into a tableau dashboard, or pivot table. | C8: I'm not sure it will be practicle to transform the overall metrics sheet from Wide to Long, However, the smaller pages should be Long not wide. See here for examples: https://byuidatascience.github.io/python4ds/tidy-data.html | E8: We need to list out which all data need to be present in the secondary table. From your POV I believe Installs to be surely present split by Week/Month and Channel | H8: TIDY DATA: WIDE TO LONG FORMAT
A9: 7 | B9: Change column names to match "Col Name Deffinitions" tab.
A10: 8 | B10: Create some light insights. | C10: Create pivot tables using the data with some common views that illustrates the weekly report but on a extended timeline (high level, not every detail needed) --- depending on how this works out, this may take place of the tableau dashboard. | E10: Decided that we will include a link to the event tracker instead in order to keep this project moving.
A11: 9 | B11: Connecting all the sheets in excel for continuity. (this can be done after piping is complete) | C11: Not sure what the best way is to do this, it may be that we add some of the over KPIs to the overall metrics sheet, or we connect using fiscal week as UID. | E11: Can be completed after Piping. (John can take up)
A12: 10 | B12: Ensure all automation pipelines are connected and working properly.
A13: 11 | B13: To accommodate the provison of Source in collated file | C13: Update: it was decided we will include a link to the event tracker. | E13: There has been lot of source changes, and we need to think on how best we can mention them in collated to avoid any future confusion
A14: 12 | B14: Restrict the formula driven columns so as to avoid any manuall update hampering the formula logic | E14: Have to check the possibility of Airflow to update the collated file if it is restricted for some of the columns

Sheet Col Name Deffinitions
A1: Location (Sheet Name) | B1: Name | C1: Data Source (include link when applicable) | D1: Purpose or description | E1: notes
A2: Primary KPIs | B2: UID_FiscalYR_FiscalWk
A3: Primary KPIs | B3: Fiscal_Year | C3: Net New | J3: Formatting Keys
A4: Primary KPIs | B4: Fiscal_Week | C4: Net New | J4: *All | K4: Further breakout exists
A5: Primary KPIs | B5: Calendar_Week_Start | C5: Net New
A6: Primary KPIs | B6: Calendar_Week_End | C6: Net New | D6: Anirban QC for all column headings
A7: Primary KPIs | B7: Installs_All | D7: Remove any extra spaces in the name (except for owned breakdown slide)
A8: Primary KPIs | B8: Installs_iOS | D8: App_Orders_All vs. App_Order_All
A9: Primary KPIs | B9: Installs_AND | D9: App_Order_All vs. Total_App_Orders
A10: Primary KPIs | B10: Installs_Organic_All
A11: Primary KPIs | B11: Installs_Organic_iOS
A12: Primary KPIs | B12: Installs_Organic_AND
A13: Primary KPIs | B13: Installs_Owned_All
A14: Primary KPIs | B14: Installs_Owned_iOS
A15: Primary KPIs | B15: Installs_Owned_AND
A16: Primary KPIs | B16: Installs_Paid_All
A17: Primary KPIs | B17: Installs_Paid_iOS
A18: Primary KPIs | B18: Installs_Paid_And
A19: Primary KPIs | B19: Installs_Paid_Atributed_All
A20: Primary KPIs | B20: Installs_Paid_Atributed_iOS
A21: Primary KPIs | B21: Installs_Paid_Atributed_And
... A78: Primary KPIs | B78: App_RetentionRate_30D_ReturningUser
A79: Primary KPIs | B79: App_WAU_New | C79: Same as weekly installs
A80: Primary KPIs | B80: App_WAU_Current | C80: <<Why is RR repeat and WAU current? Can the naming convention be aligned or is there a reason they are different?
A81: Primary KPIs | B81: App_WAU_Reactivated
A82: Primary KPIs | B82: App_WAU_Dormant_All
A83: Primary KPIs | B83: App_WAU_New_Dormant
A84: Primary KPIs | B84: App_WAU_Current_Dormant
A85: Primary KPIs | B85: App_WAU_Reactivated_Dormant
A86: Owned Breakdown
A87: paid Breakdown By Partner

Sheet QC Checklist
B2: Week | C2: ='Overall Metrics'!A1 -> 202505
B4: S.No. | C4: Sheet | D4: Description | E4: Status
B5: 1 | C5: Overall Metrics | D5: Attr. + Misatr. = Paid Overall | E5: =IFERROR(IF(VLOOKUP(C2,'Overall Metrics'!$F$7:$BK$1085,COLUMNS('Overall Metrics'!F7:N7),FALSE)=SUM(VLOOKUP(C2,'Overall Metrics'!$F$7:$BK$1085,COLUMNS('Overall Metrics'!F7:AV7),FALSE),VLOOKUP(C2,'Overall Metrics'!$F$7:$BK$1085,COLUMNS('Overall Metrics'!F7:AY7),FALSE)),"OK","Sum of attributed and misattributed does not equal paid overall."),"") -> OK
D6: Android: Org + Owned + Paid = Installs | E6: =IFERROR(IF(VLOOKUP(C2,'Overall Metrics'!$F$7:$BK$1085,COLUMNS('Overall Metrics'!F7:H7),FALSE)=SUM(VLOOKUP(C2,'Overall Metrics'!$F$7:$BK$1085,COLUMNS('Overall Metrics'!F7:AZ7),FALSE),VLOOKUP(C2,'Overall Metrics'!$F$7:$BK$1085,COLUMNS('Overall Metrics'!F7:BB7),FALSE),VLOOKUP(C2,'Overall Metrics'!$F$7:$BK$1085,COLUMNS('Overall Metrics'!F7:BD7),FALSE)),"OK","Sum of category installs does not equal all Android installs."),"") -> OK
D7: iOS: Org + Owned + Paid = Installs | E7: =IFERROR(IF(VLOOKUP(C2,'Overall Metrics'!$F$7:$BK$1085,COLUMNS('Overall Metrics'!F7:I7),FALSE)=SUM(VLOOKUP(C2,'Overall Metrics'!$F$7:$BK$1085,COLUMNS('Overall Metrics'!F7:BA7),FALSE),VLOOKUP(C2,'Overall Metrics'!$F$7:$BK$1085,COLUMNS('Overall Metrics'!F7:BC7),FALSE),VLOOKUP(C2,'Overall Metrics'!$F$7:$BK$1085,COLUMNS('Overall Metrics'!F7:BE7),FALSE)),"OK","Sum of category installs does not equal all iOS installs."),"") -> OK
D8: WoW Install Variance | E8: =IFERROR(IF(OR('Overall Metrics'!G1>=0.1,'Overall Metrics'!G1<=-0.1),"WoW variation in installs is more than 10% - debug / figure out the drivers", "No action."),"") -> No action.
D9: YoY Install Variance | E9: =IFERROR(IF(OR('Overall Metrics'!G2>=0.1,'Overall Metrics'!G2<=-0.1),"YoY variation in installs is more than 10% - debug / figure out the drivers", "No action."),"") -> No action.
D10: All Spend Equals sum of Android and iOS | E10: =IFERROR(IF(ABS(VLOOKUP(C2,'Overall Metrics'!$F$7:$BK$1085,COLUMNS('Overall Metrics'!$F:$W),FALSE)-SUM(VLOOKUP(C2,'Overall Metrics'!$F$7:$BK$1085,COLUMNS('Overall Metrics'!$F:$Z),FALSE),VLOOKUP(C2,'Overall Metrics'!$F$7:$BK$1085,COLUMNS('Overall Metrics'!$F:$AA),FALSE))<=1),"OK","Sum of Android and iOS does not equal all spend."),"") -> OK
B11: 2 | C11: Channel & Campaign Metrics | D11: Misattr. figures match on Overall Metrics and Channel & Campaign Sheet | E11: =IFERROR(IF(VLOOKUP(C2,'Overall Metrics'!$F$7:$BK$334,COLUMNS('Overall Metrics'!$F:$AY),FALSE)=VLOOKUP(C2,'Channel & Campaign Metrics'!$F$6:$BX$400,COLUMNS('Channel & Campaign Metrics'!$F:$Y),FALSE),"OK","There is a discrepancy."),"") -> OK
D12: WoW MAI Spend Variance | E12: =IFERROR(IF(OR('Channel & Campaign Metrics'!AR1>=0.1,'Channel & Campaign Metrics'!AR1<=-0.1),"More than 10% variation WoW. Debug / figure out the reason","OK"),"") -> OK
D13: WoW CPI Variance | E13: =IFERROR(IF(OR('Channel & Campaign Metrics'!BI1>=0.1,'Channel & Campaign Metrics'!BI1<=-0.1),"More than 10% variation WoW. Debug / figure out the reason","OK"),"") -> More than 10% variation WoW. Debug / figure out the reason
D14: WoW MAE Spend Variance | E14: =IFERROR(IF(OR('Channel & Campaign Metrics'!BN1>=0.1,'Channel & Campaign Metrics'!BN1<=-0.1),"More than 10% variation WoW. Debug / figure out the reason","OK"),"") -> OK
D15: WoW CPA Variance | E15: =IFERROR(IF(OR('Channel & Campaign Metrics'!BX1>=0.1,'Channel & Campaign Metrics'!BX1<=-0.1),"More than 10% variation WoW. Debug / figure out the reason","OK"),"") -> More than 10% variation WoW. Debug / figure out the reason
B16: 3 | C16: Glass Metrics | D16: App Orders - WoW Variation | E16: =IFERROR(IF(OR('Glass Metrics'!I1>=0.1,'Glass Metrics'!I1<=-0.1),"More than 10% variation WoW. Debug / figure out the reason.","OK"),"") -> More than 10% variation WoW. Debug / figure out the reason.
D17: App GMV - WoW Variation | E17: =IFERROR(IF(OR('Glass Metrics'!N1>=0.1,'Glass Metrics'!N1<=-0.1),"More than 10% variation WoW. Debug / figure out the reason.","OK"),"") -> More than 10% variation WoW. Debug / figure out the reason.
D18: App Visits - WoW Variation | E18: =IFERROR(IF(OR('Glass Metrics'!S1>=0.1,'Glass Metrics'!S1<=-0.1),"More than 10% variation WoW. Debug / figure out the reason.","OK"),"") -> More than 10% variation WoW. Debug / figure out the reason.
D19: App WAU - WoW Variation | E19: =IFERROR(IF(OR('Glass Metrics'!AC1>=0.1,'Glass Metrics'!AC1<=-0.1),"More than 10% variation WoW. Debug / figure out the reason.","OK"),"") -> More than 10% variation WoW. Debug / figure out the reason.
B20: 4 | C20: Lifecycle (Glass) | D20: Make sure WAU is close to active users in this sheet. | E20: =IFERROR(IF(ABS((VLOOKUP(C2,'Glass Metrics'!$F$7:$AU$400,COLUMNS('Glass Metrics'!F:AC),FALSE)/VLOOKUP(C2,'Lifecycle (Glass)'!F6:Y400,COLUMNS('Lifecycle (Glass)'!F:G),FALSE))-1)<=0.03,"OK","More than 3% discrepancy."),"") -> More than 3% discrepancy.
B21: 5 | C21: Customer Segmentation | D21: Customers count in Glass Metrics should match with Customer Segmentation | E21: =IFERROR(IF(ABS(VLOOKUP(C2,'Glass Metrics'!$F$7:$AU$400,COLUMNS('Glass Metrics'!F:X),FALSE)/VLOOKUP(C2,'Customer Segmentation'!$F$9:$R$400,COLUMNS('Customer Segmentation'!F:J),FALSE) - 1)<0.015,"OK","Numbers vary signficantly."),"") -> Numbers vary signficantly.

Sheet Overall Metrics
A1: =VLOOKUP(E1,E7:F319,2,FALSE) -> 202505 | D1: =E1-6 -> 45717 | E1: 45723 | F1: WoW | G1: =IFERROR(VLOOKUP($A$1,$F$7:G319,COLUMNS($F$7:G319),FALSE)/VLOOKUP(($A$1-IF(RIGHT($A$1,2)="01",48,1)),$F$7:G319,COLUMNS($F$7:G319),FALSE)-1,"NA") -> -0.065550208 | H1: =IFERROR(VLOOKUP($A$1,$F$7:H319,COLUMNS($F$7:H319),FALSE)/VLOOKUP(($A$1-IF(RIGHT($A$1,2)="01",48,1)),$F$7:H319,COLUMNS($F$7:H319),FALSE)-1,"NA") -> -0.18452123 | I1: =IFERROR(VLOOKUP($A$1,$F$7:I319,COLUMNS($F$7:I319),FALSE)/VLOOKUP(($A$1-IF(RIGHT($A$1,2)="01",48,1)),$F$7:I319,COLUMNS($F$7:I319),FALSE)-1,"NA") -> 0.01269585 | J1: =IFERROR(VLOOKUP($A$1,$F$7:J319,COLUMNS($F$7:J319),FALSE)-VLOOKUP(($A$1-IF(RIGHT($A$1,2)="01",48,1)),$F$7:J319,COLUMNS($F$7:J319),FALSE),"NA") -> -0.050513 | K1: =IFERROR(VLOOKUP($A$1,$F$7:K319,COLUMNS($F$7:K319),FALSE)-VLOOKUP(($A$1-IF(RIGHT($A$1,2)="01",48,1)),$F$7:K319,COLUMNS($F$7:K319),FALSE),"NA") -> 0.050513 | L1: =IFERROR(VLOOKUP($A$1,$F$7:L319,COLUMNS($F$7:L319),FALSE)/VLOOKUP(($A$1-IF(RIGHT($A$1,2)="01",48,1)),$F$7:L319,COLUMNS($F$7:L319),FALSE)-1,"NA") -> -0.065550208 | M1: =IFERROR(VLOOKUP($A$1,$F$7:M319,COLUMNS($F$7:M319),FALSE)/VLOOKUP(($A$1-IF(RIGHT($A$1,2)="01",48,1)),$F$7:M319,COLUMNS($F$7:M319),FALSE)-1,"NA") -> -0.14241588 | N1: =IFERROR(VLOOKUP($A$1,$F$7:N319,COLUMNS($F$7:N319),FALSE)/VLOOKUP(($A$1-IF(RIGHT($A$1,2)="01",48,1)),$F$7:N319,COLUMNS($F$7:N319),FALSE)-1,"NA") -> 0.12931912 | O1: =IFERROR(VLOOKUP($A$1,$F$7:O319,COLUMNS($F$7:O319),FALSE)-VLOOKUP(($A$1-IF(RIGHT($A$1,2)="01",48,1)),$F$7:O319,COLUMNS($F$7:O319),FALSE),"NA") -> 5.5511151e-17 | P1: =IFERROR(VLOOKUP($A$1,$F$7:P319,COLUMNS($F$7:P319),FALSE)-VLOOKUP(($A$1-IF(RIGHT($A$1,2)="01",48,1)),$F$7:P319,COLUMNS($F$7:P319),FALSE),"NA") -> -0.031460512 | Q1: =IFERROR(VLOOKUP($A$1,$F$7:Q319,COLUMNS($F$7:Q319),FALSE)-VLOOKUP(($A$1-IF(RIGHT($A$1,2)="01",48,1)),$F$7:Q319,COLUMNS($F$7:Q319),FALSE),"NA") -> 0.039327827 | R1: =IFERROR(VLOOKUP($A$1,$F$7:R319,COLUMNS($F$7:R319),FALSE)/VLOOKUP(($A$1-IF(RIGHT($A$1,2)="01",48,1)),$F$7:R319,COLUMNS($F$7:R319),FALSE)-1,"NA") -> 0.20210639 | S1: =IFERROR(VLOOKUP($A$1,$F$7:S319,COLUMNS($F$7:S319),FALSE)/VLOOKUP(($A$1-IF(RIGHT($A$1,2)="01",48,1)),$F$7:S319,COLUMNS($F$7:S319),FALSE)-1,"NA") -> -0.31147281 | T1: =IFERROR(VLOOKUP($A$1,$F$7:T319,COLUMNS($F$7:T319),FALSE)/VLOOKUP(($A$1-IF(RIGHT($A$1,2)="01",48,1)),$F$7:T319,COLUMNS($F$7:T319),FALSE)-1,"NA") -> 0.25157674 | U1: =IFERROR(VLOOKUP($A$1,$F$7:U319,COLUMNS($F$7:U319),FALSE)/VLOOKUP(($A$1-IF(RIGHT($A$1,2)="01",48,1)),$F$7:U319,COLUMNS($F$7:U319),FALSE)-1,"NA") -> 0.29700952 | V1: =IFERROR(VLOOKUP($A$1,$F$7:V319,COLUMNS($F$7:V319),FALSE)/VLOOKUP(($A$1-IF(RIGHT($A$1,2)="01",48,1)),$F$7:V319,COLUMNS($F$7:V319),FALSE)-1,"NA") -> 0.19622233 | W1: =IFERROR(VLOOKUP($A$1,$F$7:W319,COLUMNS($F$7:W319),FALSE)/VLOOKUP(($A$1-IF(RIGHT($A$1,2)="01",48,1)),$F$7:W319,COLUMNS($F$7:W319),FALSE)-1,"NA") -> -0.070066834 | X1: =IFERROR(VLOOKUP($A$1,$F$7:X319,COLUMNS($F$7:X319),FALSE)/VLOOKUP(($A$1-IF(RIGHT($A$1,2)="01",48,1)),$F$7:X319,COLUMNS($F$7:X319),FALSE)-1,"NA") -> -0.058532661 | Y1: =IFERROR(VLOOKUP($A$1,$F$7:Y319,COLUMNS($F$7:Y319),FALSE)/VLOOKUP(($A$1-IF(RIGHT($A$1,2)="01",48,1)),$F$7:Y319,COLUMNS($F$7:Y319),FALSE)-1,"NA") -> -0.094199355 | ... AF1: =IFERROR(VLOOKUP($A$1,$F$7:AF319,COLUMNS($F$7:AF319),FALSE)/VLOOKUP(($A$1-IF(RIGHT($A$1,2)="01",48,1)),$F$7:AF319,COLUMNS($F$7:AF319),FALSE)-1,"NA") -> 0.37882644 | AG1: =IFERROR(VLOOKUP($A$1,$F$7:AG319,COLUMNS($F$7:AG319),FALSE)-VLOOKUP(($A$1-IF(RIGHT($A$1,2)="01",48,1)),$F$7:AG319,COLUMNS($F$7:AG319),FALSE),"NA") -> -0.29773576 | AH1: =IFERROR(VLOOKUP($A$1,$F$7:AH319,COLUMNS($F$7:AH319),FALSE)/VLOOKUP(($A$1-IF(RIGHT($A$1,2)="01",48,1)),$F$7:AH319,COLUMNS($F$7:AH319),FALSE)-1,"NA") -> 0.0029550357 | AI1: =IFERROR(VLOOKUP($A$1,$F$7:AI319,COLUMNS($F$7:AI319),FALSE)-VLOOKUP(($A$1-IF(RIGHT($A$1,2)="01",48,1)),$F$7:AI319,COLUMNS($F$7:AI319),FALSE),"NA") -> 0.28064232 | AJ1: {=IFERROR(VLOOKUP($A$1-IF(RIGHT($A$1,2)="01",48,1),$F$7:AJ319,COLUMNS($F$7:AJ319),FALSE)-VLOOKUP(($A$1-IFERROR(_xlfn.IFS(RIGHT($A$1,2)="01",49,RIGHT($A$1,2)="02",49),2)),$F$7:AJ319,COLUMNS($F$7:AJ319),FALSE),"NA")} -> 0.034551406 | AK1: {=IFERROR(VLOOKUP($A$1-IF(RIGHT($A$1,2)="01",48,1),$F$7:AK319,COLUMNS($F$7:AK319),FALSE)-VLOOKUP(($A$1-IFERROR(_xlfn.IFS(RIGHT($A$1,2)="01",49,RIGHT($A$1,2)="02",49),2)),$F$7:AK319,COLUMNS($F$7:AK319),FALSE),"NA")} -> 0.47562074 | AL1: {=IFERROR(VLOOKUP($A$1-IF(RIGHT($A$1,2)="01",48,1),$F$7:AL319,COLUMNS($F$7:AL319),FALSE)-VLOOKUP(($A$1-IFERROR(_xlfn.IFS(RIGHT($A$1,2)="01",49,RIGHT($A$1,2)="02",49),2)),$F$7:AL319,COLUMNS($F$7:AL319),FALSE),"NA")} -> -0.46020713 | AM1: {=IFERROR(VLOOKUP($A$1-IF(RIGHT($A$1,2)="01",48,1),$F$7:AM319,COLUMNS($F$7:AM319),FALSE)/VLOOKUP(($A$1-IFERROR(_xlfn.IFS(RIGHT($A$1,2)="01",49,RIGHT($A$1,2)="02",49),2)),$F$7:AM319,COLUMNS($F$7:AM319),FALSE)-1,"NA")} -> 0.41287157 | AN1: {=IFERROR(VLOOKUP($A$1-IF(RIGHT($A$1,2)="01",48,1),$F$7:AN319,COLUMNS($F$7:AN319),FALSE)/VLOOKUP(($A$1-IFERROR(_xlfn.IFS(RIGHT($A$1,2)="01",49,RIGHT($A$1,2)="02",49),2)),$F$7:AN319,COLUMNS($F$7:AN319),FALSE)-1,"NA")} -> 0.39315551 | AO1: {=IFERROR(VLOOKUP($A$1-IF(RIGHT($A$1,2)="01",48,1),$F$7:AO319,COLUMNS($F$7:AO319),FALSE)-VLOOKUP(($A$1-IFERROR(_xlfn.IFS(RIGHT($A$1,2)="01",49,RIGHT($A$1,2)="02",49),2)),$F$7:AO319,COLUMNS($F$7:AO319),FALSE),"NA")} -> 0.034551406 | AP1: {=IFERROR(VLOOKUP($A$1-IFERROR(_xlfn.IFS(RIGHT($A$1,2)="01",51,RIGHT($A$1,2)="02",51,RIGHT($A$1,2)="03",51,RIGHT($A$1,2)="04",51),4),$F$7:AP319,COLUMNS($F$7:AP319),FALSE)-VLOOKUP(($A$1-IFERROR(_xlfn.IFS(RIGHT($A$1,2)="01",52,RIGHT($A$1,2)="02",52,RIGHT($A$1,2)="03",52,RIGHT($A$1,2)="04",52,RIGHT($A$1,2)="05",52),5)),$F$7:AP319,COLUMNS($F$7:AP319),FALSE),"NA")} -> 0.53688196 | AQ1: {=IFERROR(VLOOKUP($A$1-IFERROR(_xlfn.IFS(RIGHT($A$1,2)="01",51,RIGHT($A$1,2)="02",51,RIGHT($A$1,2)="03",51,RIGHT($A$1,2)="04",51),4),$F$7:AQ319,COLUMNS($F$7:AQ319),FALSE)-VLOOKUP(($A$1-IFERROR(_xlfn.IFS(RIGHT($A$1,2)="01",52,RIGHT($A$1,2)="02",52,RIGHT($A$1,2)="03",52,RIGHT($A$1,2)="04",52,RIGHT($A$1,2)="05",52),5)),$F$7:AQ319,COLUMNS($F$7:AQ319),FALSE),"NA")} -> 0.49505614 | AR1: {=IFERROR(VLOOKUP($A$1-IFERROR(_xlfn.IFS(RIGHT($A$1,2)="01",51,RIGHT($A$1,2)="02",51,RIGHT($A$1,2)="03",51,RIGHT($A$1,2)="04",51),4),$F$7:AR319,COLUMNS($F$7:AR319),FALSE)-VLOOKUP(($A$1-IFERROR(_xlfn.IFS(RIGHT($A$1,2)="01",52,RIGHT($A$1,2)="02",52,RIGHT($A$1,2)="03",52,RIGHT($A$1,2)="04",52,RIGHT($A$1,2)="05",52),5)),$F$7:AR319,COLUMNS($F$7:AR319),FALSE),"NA")} -> 0.57870777 | AS1: {=IFERROR(VLOOKUP($A$1-IFERROR(_xlfn.IFS(RIGHT($A$1,2)="01",51,RIGHT($A$1,2)="02",51,RIGHT($A$1,2)="03",51,RIGHT($A$1,2)="04",51),4),$F$7:AS319,COLUMNS($F$7:AS319),FALSE)-VLOOKUP(($A$1-IFERROR(_xlfn.IFS(RIGHT($A$1,2)="01",52,RIGHT($A$1,2)="02",52,RIGHT($A$1,2)="03",52,RIGHT($A$1,2)="04",52,RIGHT($A$1,2)="05",52),5)),$F$7:AS319,COLUMNS($F$7:AS319),FALSE),"NA")} -> 0.53688196 | AT1: =IFERROR(VLOOKUP($A$1,$F$7:AT319,COLUMNS($F$7:AT319),FALSE)/VLOOKUP(($A$1-IF(RIGHT($A$1,2)="01",48,1)),$F$7:AT319,COLUMNS($F$7:AT319),FALSE)-1,"NA") -> 0.20189424 | AU1: =IFERROR(VLOOKUP($A$1,$F$7:AU319,COLUMNS($F$7:AU319),FALSE)/VLOOKUP(($A$1-IF(RIGHT($A$1,2)="01",48,1)),$F$7:AU319,COLUMNS($F$7:AU319),FALSE)-1,"NA") -> 0.10597792 | AV1: =IFERROR(VLOOKUP($A$1,$F$7:AV319,COLUMNS($F$7:AV319),FALSE)/VLOOKUP(($A$1-IF(RIGHT($A$1,2)="01",48,1)),$F$7:AV319,COLUMNS($F$7:AV319),FALSE)-1,"NA") -> 0.12931912 | AW1: =IFERROR(VLOOKUP($A$1,$F$7:AW319,COLUMNS($F$7:AW319),FALSE)/VLOOKUP(($A$1-IF(RIGHT($A$1,2)="01",48,1)),$F$7:AW319,COLUMNS($F$7:AW319),FALSE)-1,"NA") -> 0.20189424 | AX1: =IFERROR(VLOOKUP($A$1,$F$7:AX319,COLUMNS($F$7:AX319),FALSE)/VLOOKUP(($A$1-IF(RIGHT($A$1,2)="01",48,1)),$F$7:AX319,COLUMNS($F$7:AX319),FALSE)-1,"NA") -> 0.10597792 | AY1: =IFERROR(VLOOKUP($A$1,$F$7:AY319,COLUMNS($F$7:AY319),FALSE)/VLOOKUP(($A$1-IF(RIGHT($A$1,2)="01",48,1)),$F$7:AY319,COLUMNS($F$7:AY319),FALSE)-1,"NA") -> 0.12931912 | AZ1: =IFERROR(VLOOKUP($A$1,$F$7:AZ319,COLUMNS($F$7:AZ319),FALSE)/VLOOKUP(($A$1-IF(RIGHT($A$1,2)="01",48,1)),$F$7:AZ319,COLUMNS($F$7:AZ319),FALSE)-1,"NA") -> -0.18452123 | BA1: =IFERROR(VLOOKUP($A$1,$F$7:BA319,COLUMNS($F$7:BA319),FALSE)/VLOOKUP(($A$1-IF(RIGHT($A$1,2)="01",48,1)),$F$7:BA319,COLUMNS($F$7:BA319),FALSE)-1,"NA") -> 0.01269585 | ... BE1: =IFERROR(VLOOKUP($A$1,$F$7:BE319,COLUMNS($F$7:BE319),FALSE)/VLOOKUP(($A$1-IF(RIGHT($A$1,2)="01",48,1)),$F$7:BE319,COLUMNS($F$7:BE319),FALSE)-1,"NA") -> 0.10597792 | BF1: =IFERROR(VLOOKUP($A$1,$F$7:BF319,COLUMNS($F$7:BF319),FALSE)-VLOOKUP(($A$1-IF(RIGHT($A$1,2)="01",48,1)),$F$7:BF319,COLUMNS($F$7:BF319),FALSE),"NA") -> -0.050513 | BG1: =IFERROR(VLOOKUP($A$1,$F$7:BG319,COLUMNS($F$7:BG319),FALSE)-VLOOKUP(($A$1-IF(RIGHT($A$1,2)="01",48,1)),$F$7:BG319,COLUMNS($F$7:BG319),FALSE),"NA") -> 0.050513 | BH1: =IFERROR(VLOOKUP($A$1,$F$7:BH319,COLUMNS($F$7:BH319),FALSE)-VLOOKUP(($A$1-IF(RIGHT($A$1,2)="01",48,1)),$F$7:BH319,COLUMNS($F$7:BH319),FALSE),"NA") -> -0.082130114 | BI1: =IFERROR(VLOOKUP($A$1,$F$7:BI319,COLUMNS($F$7:BI319),FALSE)-VLOOKUP(($A$1-IF(RIGHT($A$1,2)="01",48,1)),$F$7:BI319,COLUMNS($F$7:BI319),FALSE),"NA") -> 0.082124046 | BJ1: =IFERROR(VLOOKUP($A$1,$F$7:BJ319,COLUMNS($F$7:BJ319),FALSE)-VLOOKUP(($A$1-IF(RIGHT($A$1,2)="01",48,1)),$F$7:BJ319,COLUMNS($F$7:BJ319),FALSE),"NA") -> 0.015638742 | BK1: =IFERROR(VLOOKUP($A$1,$F$7:BK319,COLUMNS($F$7:BK319),FALSE)-VLOOKUP(($A$1-IF(RIGHT($A$1,2)="01",48,1)),$F$7:BK319,COLUMNS($F$7:BK319),FALSE),"NA") -> -0.015638742 | BL1: =IFERROR(VLOOKUP($A$1,$F$7:BL319,COLUMNS($F$7:BL319),FALSE)/VLOOKUP(($A$1-IF(RIGHT($A$1,2)="01",48,1)),$F$7:BL319,COLUMNS($F$7:BL319),FALSE)-1,"NA") -> 0.11650752 | BM1: =IFERROR(VLOOKUP($A$1,$F$7:BM319,COLUMNS($F$7:BM319),FALSE)/VLOOKUP(($A$1-IF(RIGHT($A$1,2)="01",48,1)),$F$7:BM319,COLUMNS($F$7:BM319),FALSE)-1,"NA") -> 0.27885643 | BN1: =IFERROR(VLOOKUP($A$1,$F$7:BN319,COLUMNS($F$7:BN319),FALSE)/VLOOKUP(($A$1-IF(RIGHT($A$1,2)="01",48,1)),$F$7:BN319,COLUMNS($F$7:BN319),FALSE)-1,"NA") -> 0.20307449
F2: YoY | G2: =IFERROR(VLOOKUP($A$1,$F$7:G319,COLUMNS($F$7:G319),FALSE)/VLOOKUP(($A$1-99),$F$7:G267,COLUMNS($F$7:G319),FALSE)-1,"NA") -> 0.061082969 | H2: =IFERROR(VLOOKUP($A$1,$F$7:H319,COLUMNS($F$7:H319),FALSE)/VLOOKUP(($A$1-99),$F$7:H319,COLUMNS($F$7:H319),FALSE)-1,"NA") -> -0.15347916 | I2: =IFERROR(VLOOKUP($A$1,$F$7:I319,COLUMNS($F$7:I319),FALSE)/VLOOKUP(($A$1-99),$F$7:I319,COLUMNS($F$7:I319),FALSE)-1,"NA") -> 0.2256036 | J2: =IFERROR(VLOOKUP($A$1,$F$7:J319,COLUMNS($F$7:J319),FALSE)-VLOOKUP(($A$1-99),$F$7:J319,COLUMNS($F$7:J319),FALSE),"NA") -> -0.087758673 | K2: =IFERROR(VLOOKUP($A$1,$F$7:K319,COLUMNS($F$7:K319),FALSE)-VLOOKUP(($A$1-99),$F$7:K319,COLUMNS($F$7:K319),FALSE),"NA") -> 0.087758673 | L2: =IFERROR(VLOOKUP($A$1,$F$7:L319,COLUMNS($F$7:L319),FALSE)/VLOOKUP(($A$1-99),$F$7:L319,COLUMNS($F$7:L319),FALSE)-1,"NA") -> 0.061082969 | M2: =IFERROR(VLOOKUP($A$1,$F$7:M319,COLUMNS($F$7:M319),FALSE)/VLOOKUP(($A$1-99),$F$7:M319,COLUMNS($F$7:M319),FALSE)-1,"NA") -> 0.061727727 | N2: =IFERROR(VLOOKUP($A$1,$F$7:N319,COLUMNS($F$7:N319),FALSE)/VLOOKUP(($A$1-99),$F$7:N319,COLUMNS($F$7:N319),FALSE)-1,"NA") -> 0.059843542 | O2: =IFERROR(VLOOKUP($A$1,$F$7:O319,COLUMNS($F$7:O319),FALSE)-VLOOKUP(($A$1-99),$F$7:O319,COLUMNS($F$7:O319),FALSE),"NA") -> 5.5511151e-17 | P2: =IFERROR(VLOOKUP($A$1,$F$7:P319,COLUMNS($F$7:P319),FALSE)-VLOOKUP(($A$1-99),$F$7:P319,COLUMNS($F$7:P319),FALSE),"NA") -> 0.00021315422 | Q2: =IFERROR(VLOOKUP($A$1,$F$7:Q319,COLUMNS($F$7:Q319),FALSE)-VLOOKUP(($A$1-99),$F$7:Q319,COLUMNS($F$7:Q319),FALSE),"NA") -> -0.00026653384 | R2: =IFERROR(VLOOKUP($A$1,$F$7:R319,COLUMNS($F$7:R319),FALSE)/VLOOKUP(($A$1-99),$F$7:R319,COLUMNS($F$7:R319),FALSE)-1,"NA") -> 0.028694205 | S2: =IFERROR(VLOOKUP($A$1,$F$7:S319,COLUMNS($F$7:S319),FALSE)/VLOOKUP(($A$1-99),$F$7:S319,COLUMNS($F$7:S319),FALSE)-1,"NA") -> -0.19808274 | T2: =IFERROR(VLOOKUP($A$1,$F$7:T319,COLUMNS($F$7:T319),FALSE)/VLOOKUP(($A$1-99),$F$7:T319,COLUMNS($F$7:T319),FALSE)-1,"NA") -> -0.12029185 | U2: =IFERROR(VLOOKUP($A$1,$F$7:U319,COLUMNS($F$7:U319),FALSE)/VLOOKUP(($A$1-99),$F$7:U319,COLUMNS($F$7:U319),FALSE)-1,"NA") -> -0.22562582 | V2: =IFERROR(VLOOKUP($A$1,$F$7:V319,COLUMNS($F$7:V319),FALSE)/VLOOKUP(($A$1-99),$F$7:V319,COLUMNS($F$7:V319),FALSE)-1,"NA") -> -0.13307501 | W2: =IFERROR(VLOOKUP($A$1,$F$7:W319,COLUMNS($F$7:W319),FALSE)/VLOOKUP(($A$1-99),$F$7:W319,COLUMNS($F$7:W319),FALSE)-1,"NA") -> 0.22851984 | X2: =IFERROR(VLOOKUP($A$1,$F$7:X319,COLUMNS($F$7:X319),FALSE)/VLOOKUP(($A$1-99),$F$7:X319,COLUMNS($F$7:X319),FALSE)-1,"NA") -> -0.079418141 | Y2: =IFERROR(VLOOKUP($A$1,$F$7:Y319,COLUMNS($F$7:Y319),FALSE)/VLOOKUP(($A$1-99),$F$7:Y319,COLUMNS($F$7:Y319),FALSE)-1,"NA") -> 3.5071297 | ... AF2: =IFERROR(VLOOKUP($A$1,$F$7:AF319,COLUMNS($F$7:AF319),FALSE)/VLOOKUP(($A$1-99),$F$7:AF319,COLUMNS($F$7:AF319),FALSE)-1,"NA") -> 0.48268919 | AG2: =IFERROR(VLOOKUP($A$1,$F$7:AG319,COLUMNS($F$7:AG319),FALSE)-VLOOKUP(($A$1-99),$F$7:AG319,COLUMNS($F$7:AG319),FALSE),"NA") -> -0.23174496 | AH2: =IFERROR(VLOOKUP($A$1,$F$7:AH319,COLUMNS($F$7:AH319),FALSE)/VLOOKUP(($A$1-99),$F$7:AH319,COLUMNS($F$7:AH319),FALSE)-1,"NA") -> 0.23220917 | AI2: =IFERROR(VLOOKUP($A$1,$F$7:AI319,COLUMNS($F$7:AI319),FALSE)-VLOOKUP(($A$1-99),$F$7:AI319,COLUMNS($F$7:AI319),FALSE),"NA") -> 0.88357987 | AJ2: =IFERROR(VLOOKUP(($A$1-IF(RIGHT($A$1,2)="01",48,1)),$F$7:AJ319,COLUMNS($F$7:AJ319),FALSE)-VLOOKUP(($A$1-IF(RIGHT($A$1,2)="01",100,100)),$F$7:AJ319,COLUMNS($F$7:AJ319),FALSE),"NA") -> -0.32647402 | AK2: =IFERROR(VLOOKUP(($A$1-IF(RIGHT($A$1,2)="01",48,1)),$F$7:AK319,COLUMNS($F$7:AK319),FALSE)-VLOOKUP(($A$1-IF(RIGHT($A$1,2)="01",100,100)),$F$7:AK319,COLUMNS($F$7:AK319),FALSE),"NA") -> -0.42592911 | AL2: =IFERROR(VLOOKUP(($A$1-IF(RIGHT($A$1,2)="01",48,1)),$F$7:AL319,COLUMNS($F$7:AL319),FALSE)-VLOOKUP(($A$1-IF(RIGHT($A$1,2)="01",100,100)),$F$7:AL319,COLUMNS($F$7:AL319),FALSE),"NA") -> -0.25597689 | AM2: =IFERROR(VLOOKUP(($A$1-IF(RIGHT($A$1,2)="01",48,1)),$F$7:AM319,COLUMNS($F$7:AM319),FALSE)/VLOOKUP(($A$1-IF(RIGHT($A$1,2)="01",100,100)),$F$7:AM319,COLUMNS($F$7:AM319),FALSE)-1,"NA") -> 0.81324141 | AN2: =IFERROR(VLOOKUP(($A$1-IF(RIGHT($A$1,2)="01",48,1)),$F$7:AN319,COLUMNS($F$7:AN319),FALSE)/VLOOKUP(($A$1-IF(RIGHT($A$1,2)="01",100,100)),$F$7:AN319,COLUMNS($F$7:AN319),FALSE)-1,"NA") -> 0.48150923 | AO2: =IFERROR(VLOOKUP(($A$1-IF(RIGHT($A$1,2)="01",48,1)),$F$7:AO319,COLUMNS($F$7:AO319),FALSE)-VLOOKUP(($A$1-IF(RIGHT($A$1,2)="01",100,100)),$F$7:AO319,COLUMNS($F$7:AO319),FALSE),"NA") -> -0.32647402 | AP2: =IFERROR(VLOOKUP(($A$1-IF(OR(RIGHT($A$1,2)="01",RIGHT($A$1,2)="02",RIGHT($A$1,2)="03",RIGHT($A$1,2)="04"),51,4)),$F$7:AP319,COLUMNS($F$7:AP319),FALSE)-VLOOKUP(($A$1-IF(OR(RIGHT($A$1,2)="01",RIGHT($A$1,2)="02",RIGHT($A$1,2)="03"),151,103)),$F$7:AP319,COLUMNS($F$7:AP319),FALSE),"NA") -> 0.66889427 | AQ2: =IFERROR(VLOOKUP(($A$1-IF(OR(RIGHT($A$1,2)="01",RIGHT($A$1,2)="02",RIGHT($A$1,2)="03",RIGHT($A$1,2)="04"),51,4)),$F$7:AQ319,COLUMNS($F$7:AQ319),FALSE)-VLOOKUP(($A$1-IF(OR(RIGHT($A$1,2)="01",RIGHT($A$1,2)="02",RIGHT($A$1,2)="03"),151,103)),$F$7:AQ319,COLUMNS($F$7:AQ319),FALSE),"NA") -> 0.2564579 | AR2: =IFERROR(VLOOKUP(($A$1-IF(OR(RIGHT($A$1,2)="01",RIGHT($A$1,2)="02",RIGHT($A$1,2)="03",RIGHT($A$1,2)="04"),51,4)),$F$7:AR319,COLUMNS($F$7:AR319),FALSE)-VLOOKUP(($A$1-IF(OR(RIGHT($A$1,2)="01",RIGHT($A$1,2)="02",RIGHT($A$1,2)="03"),151,103)),$F$7:AR319,COLUMNS($F$7:AR319),FALSE),"NA") -> 0.28981003 | AS2: =IFERROR(VLOOKUP(($A$1-IF(OR(RIGHT($A$1,2)="01",RIGHT($A$1,2)="02",RIGHT($A$1,2)="03",RIGHT($A$1,2)="04"),51,4)),$F$7:AS319,COLUMNS($F$7:AS319),FALSE)-VLOOKUP(($A$1-IF(OR(RIGHT($A$1,2)="01",RIGHT($A$1,2)="02",RIGHT($A$1,2)="03"),151,103)),$F$7:AS319,COLUMNS($F$7:AS319),FALSE),"NA") -> 0.66889427 | AT2: =IFERROR(VLOOKUP($A$1,$F$7:AT319,COLUMNS($F$7:AT319),FALSE)/VLOOKUP(($A$1-99),$F$7:AT319,COLUMNS($F$7:AT319),FALSE)-1,"NA") -> 0.50281259 | AU2: =IFERROR(VLOOKUP($A$1,$F$7:AU319,COLUMNS($F$7:AU319),FALSE)/VLOOKUP(($A$1-99),$F$7:AU319,COLUMNS($F$7:AU319),FALSE)-1,"NA") -> -0.039144338 | AV2: =IFERROR(VLOOKUP($A$1,$F$7:AV319,COLUMNS($F$7:AV319),FALSE)/VLOOKUP(($A$1-99),$F$7:AV319,COLUMNS($F$7:AV319),FALSE)-1,"NA") -> 0.059843542 | AW2: =IFERROR(VLOOKUP($A$1,$F$7:AW319,COLUMNS($F$7:AW319),FALSE)/VLOOKUP(($A$1-99),$F$7:AW319,COLUMNS($F$7:AW319),FALSE)-1,"NA") -> 0.50281259 | AX2: =IFERROR(VLOOKUP($A$1,$F$7:AX319,COLUMNS($F$7:AX319),FALSE)/VLOOKUP(($A$1-99),$F$7:AX319,COLUMNS($F$7:AX319),FALSE)-1,"NA") -> -0.039144338 | AY2: =IFERROR(VLOOKUP($A$1,$F$7:AY319,COLUMNS($F$7:AY319),FALSE)/VLOOKUP(($A$1-99),$F$7:AY319,COLUMNS($F$7:AY319),FALSE)-1,"NA") -> 0.059843542 | AZ2: =IFERROR(VLOOKUP($A$1,$F$7:AZ319,COLUMNS($F$7:AZ319),FALSE)/VLOOKUP(($A$1-99),$F$7:AZ319,COLUMNS($F$7:AZ319),FALSE)-1,"NA") -> -0.15347916 | BA2: =IFERROR(VLOOKUP($A$1,$F$7:BA319,COLUMNS($F$7:BA319),FALSE)/VLOOKUP(($A$1-99),$F$7:BA319,COLUMNS($F$7:BA319),FALSE)-1,"NA") -> 0.2256036 | ... BE2: =IFERROR(VLOOKUP($A$1,$F$7:BE319,COLUMNS($F$7:BE319),FALSE)/VLOOKUP(($A$1-99),$F$7:BE319,COLUMNS($F$7:BE319),FALSE)-1,"NA") -> -0.039144338 | BF2: =IFERROR(VLOOKUP($A$1,$F$7:BF319,COLUMNS($F$7:BF319),FALSE)-VLOOKUP(($A$1-99),$F$7:BF319,COLUMNS($F$7:BF319),FALSE),"NA") -> -0.087758673 | BG2: =IFERROR(VLOOKUP($A$1,$F$7:BG319,COLUMNS($F$7:BG319),FALSE)-VLOOKUP(($A$1-99),$F$7:BG319,COLUMNS($F$7:BG319),FALSE),"NA") -> 0.087758673 | BH2: =IFERROR(VLOOKUP($A$1,$F$7:BH319,COLUMNS($F$7:BH319),FALSE)-VLOOKUP(($A$1-99),$F$7:BH319,COLUMNS($F$7:BH319),FALSE),"NA") -> -0.21654122 | BI2: =IFERROR(VLOOKUP($A$1,$F$7:BI319,COLUMNS($F$7:BI319),FALSE)-VLOOKUP(($A$1-99),$F$7:BI319,COLUMNS($F$7:BI319),FALSE),"NA") -> 0.21654148 | BJ2: =IFERROR(VLOOKUP($A$1,$F$7:BJ319,COLUMNS($F$7:BJ319),FALSE)-VLOOKUP(($A$1-99),$F$7:BJ319,COLUMNS($F$7:BJ319),FALSE),"NA") -> 0.076339423 | BK2: =IFERROR(VLOOKUP($A$1,$F$7:BK319,COLUMNS($F$7:BK319),FALSE)-VLOOKUP(($A$1-99),$F$7:BK319,COLUMNS($F$7:BK319),FALSE),"NA") -> -0.076339423 | BL2: =IFERROR(VLOOKUP($A$1,$F$7:BL319,COLUMNS($F$7:BL319),FALSE)/VLOOKUP(($A$1-99),$F$7:BL319,COLUMNS($F$7:BL319),FALSE)-1,"NA") -> -0.028586596 | BM2: =IFERROR(VLOOKUP($A$1,$F$7:BM319,COLUMNS($F$7:BM319),FALSE)/VLOOKUP(($A$1-99),$F$7:BM319,COLUMNS($F$7:BM319),FALSE)-1,"NA") -> 0.56067791 | BN2: =IFERROR(VLOOKUP($A$1,$F$7:BN319,COLUMNS($F$7:BN319),FALSE)/VLOOKUP(($A$1-99),$F$7:BN319,COLUMNS($F$7:BN319),FALSE)-1,"NA") -> 0.23590681
F3: Primary Source | G3: (AppsFlyer) | H3: (AppsFlyer) | I3: (AppsFlyer) | J3: (Derived) | K3: (Derived) | L3: (AppsFlyer) | M3: (AppsFlyer) | N3: (AppsFlyer) | O3: (Derived) | P3: (Derived) | Q3: (Derived) | R3: (Linked) | S3: (Linked) | T3: (Derived) | U3: (Derived) | V3: (Derived) | W3: (Derived) | X3: (Linked) | Y3: (Linked) | Z3: (PubW) | AA3: (PubW) | AB3: (Linked - Amplitude) | AC3: (Linked - SOL_V) | AD3: (Linked - SOL_V) | AE3: (Linked - Adobe) | AF3: (Derived) | AG3: (Derived) | AH3: (Derived) | AI3: (Derived) | AJ3: (Derived) | AK3: (Amplitude) | AL3: (Amplitude) | AM3: (Amplitude) | AN3: (Amplitude) | AO3: (Derived) | AP3: (Derived) | AQ3: (Amplitude) | AR3: (Amplitude) | AS3: (Derived) | AT3: (AppsFlyer) | AU3: (AppsFlyer) | AV3: (Derived) | AW3: (Derived) | AX3: (Derived) | AY3: (Derived) | AZ3: (Derived) | BA3: (Derived) | BB3: (AppsFlyer) | BC3: (AppsFlyer) | BD3: (AppsFlyer) | BE3: (AppsFlyer) | BF3: (Derived) | BG3: (Derived) | BH3: (Derived) | BI3: (Derived) | BJ3: (Derived) | BK3: (Derived) | BL3: (Omniture) | BM3: (Omniture) | BN3: (Derived)
F4: Secondary Source | G4: (ST360) | H4: (ST360) | I4: (ST360) | L4: (ST360) | AK4: (Adjusted) | AO4: (Adjusted) | AQ4: (Adjusted) | AS4: (Adjusted)
A6: Fiscal_Year | B6: Fiscal_Week | C6: Fiscal_Quarter | D6: Calendar_Week_Start | E6: Calendar_Week_End | F6: Week_UID | G6: Installs_All | H6: Installs_ AND | I6: Installs_ iOS | J6: Installs_AND_Share | K6: Installs_iOS_Share | L6: Installs_ Organic_All | M6: Installs_ Owned_All | N6: Installs_Paid_All | O6: Installs_ Organic_Share | P6: Installs_ Owned_Share | Q6: Installs_Paid_Share | R6: Installs_ Forecast_All | S6: Installs_Plan_All_Rev | T6: Installs_Actual_All_YTD | U6: Installs_Forecast_All_YTD | V6: Installs_Plan_All_YTD_Rev | W6: Spend_All | X6: Spend_Paid_MAI | Y6: Spend_Paid_MAE | Z6: Spend_AND | AA6: Spend_iOS | AB6: App_WAU_All | AC6: App_Orders_All | AD6: App_Revenue_All | AE6: App_Visits_All | AF6: App_Session_per_User | AG6: App_ CvR_All | AH6: App_ AOV_All | AI6: Growth_ Index | AJ6: App_7D_RR_All | AK6: App_7D_RR_iOS | AL6: App_7D_RR_AND | AM6: 7D_RR_iOS_Installs | AN6: 7D_RR_AND_Installs | AO6: App_7D_RR_All_Estimate | AP6: App_30D_RR_All | AQ6: App_30D_RR_iOS | AR6: App_30D_RR_AND | AS6: App_30D_RR_All_Estimate | AT6: Installs_Paid_MAI_Attributed_AND | AU6: Installs_Paid_MAI_Attributed_iOS | AV6: Installs_Paid_MAI_Attributed_All | AW6: Installs_Paid_MAI_Misattributed_AND | AX6: Installs_Paid_MAI_Misattributed_iOS | AY6: Installs_Paid_MAI_Misattributed_All | AZ6: Installs_ Organic_AND | BA6: Installs_ Organic_iOS | BB6: Installs_ Owned_AND | BC6: Installs_ Owned_iOS | BD6: Installs_Paid_AND | BE6: Installs_Paid_iOS | BF6: Installs_Organic_AND_Share | BG6: Installs_Organic_iOS_Share | BH6: Installs_Owned_AND_Share | BI6: Installs_Owned_iOS_Share | BJ6: Installs_Paid_AND_Share | BK6: Installs_Paid_iOS_Share | BL6: InStore_ Sessions_iOS | BM6: InStore_ Sessions_AND | BN6: InStore_ Sessions_ALL
A7: =LEFT(F7,4)+1 -> 2021 | B7: =RIGHT(F7,2) -> 01 | C7: {=_xlfn.IFS(_xlfn.NUMBERVALUE(B7)<=13,"Q1",AND(_xlfn.NUMBERVALUE(B7)>13,_xlfn.NUMBERVALUE(B7)<=26),"Q2", AND(_xlfn.NUMBERVALUE(B7)>26,_xlfn.NUMBERVALUE(B7)<=39),"Q3",_xlfn.NUMBERVALUE(B7)>39,"Q4")} -> Q1 | D7: 43862 | E7: =D7+6 -> 43868 | F7: 202001 | G7: =SUM(H7:I7) -> 0 | J7: =IFERROR(H7/G7,0) -> 0 | K7: =IFERROR(I7/G7,0) -> 0 | O7: =IFERROR(L7/$G7,0) -> 0 | P7: =IFERROR(M7/$G7,0) -> 0 | Q7: =IFERROR(N7/$G7,0) -> 0 | R7: =Forecast!J2 -> 0 | S7: =Forecast!N2 -> 0 | T7: =IF(OR(RIGHT(F7,2) = "01",G7 = 0),G7,T6+G7) -> 0 | U7: =IF(RIGHT(F7,2)="01",R7,R7+U6) -> 0 | V7: =IF(RIGHT(F7,2)="01",S7,S7+V6) -> 0 | W7: =X7+Y7 -> 0 | X7: ='Channel & Campaign Metrics'!AR6 -> 0 | Y7: ='Channel & Campaign Metrics'!BS6 -> 0 | AB7: ='Glass Metrics'!AC7 -> 0 | AC7: ='Glass Metrics'!I7 -> 0 | AD7: ='Glass Metrics'!N7 -> 0 | AE7: ='Glass Metrics'!S7 -> 0 | AF7: =IFERROR(AE7/AB7,"") | AG7: =IFERROR(AC7/AE7,"") | AH7: =IFERROR(AD7/AC7,"") | AI7: =IFERROR(G7/AB7,"") | AO7: =AJ7 -> 0 | AS7: =AP7 -> 0 | AV7: =SUM(AT7:AU7) -> 0 | BN7: =SUM(BL7:BM7) -> 0
A8: =LEFT(F8,4)+1 -> 2021 | B8: =RIGHT(F8,2) -> 02 | C8: {=_xlfn.IFS(_xlfn.NUMBERVALUE(B8)<=13,"Q1",AND(_xlfn.NUMBERVALUE(B8)>13,_xlfn.NUMBERVALUE(B8)<=26),"Q2", AND(_xlfn.NUMBERVALUE(B8)>26,_xlfn.NUMBERVALUE(B8)<=39),"Q3",_xlfn.NUMBERVALUE(B8)>39,"Q4")} -> Q1 | D8: =E7+1 -> 43869 | E8: =D8+6 -> 43875 | F8: 202002 | G8: =SUM(H8:I8) -> 0 | J8: =IFERROR(H8/G8,0) -> 0 | K8: =IFERROR(I8/G8,0) -> 0 | O8: =IFERROR(L8/$G8,0) -> 0 | P8: =IFERROR(M8/$G8,0) -> 0 | Q8: =IFERROR(N8/$G8,0) -> 0 | R8: =Forecast!J3 -> 0 | S8: =Forecast!N3 -> 0 | T8: =IF(OR(RIGHT(F8,2) = "01",G8 = 0),G8,T7+G8) -> 0 | U8: =IF(RIGHT(F8,2)="01",R8,R8+U7) -> 0 | V8: =IF(RIGHT(F8,2)="01",S8,S8+V7) -> 0 | W8: =X8+Y8 -> 0 | X8: ='Channel & Campaign Metrics'!AR7 -> 0 | Y8: ='Channel & Campaign Metrics'!BS7 -> 0 | AB8: ='Glass Metrics'!AC8 -> 0 | AC8: ='Glass Metrics'!I8 -> 0 | AD8: ='Glass Metrics'!N8 -> 0 | AE8: ='Glass Metrics'!S8 -> 0 | AF8: =IFERROR(AE8/AB8,"") | AG8: =IFERROR(AC8/AE8,"") | AH8: =IFERROR(AD8/AC8,"") | AI8: =IFERROR(G8/AB8,"") | AO8: =AJ8 -> 0 | AS8: =AP8 -> 0 | AV8: =SUM(AT8:AU8) -> 0 | BN8: =SUM(BL8:BM8) -> 0
A9: =LEFT(F9,4)+1 -> 2021 | B9: =RIGHT(F9,2) -> 03 | C9: {=_xlfn.IFS(_xlfn.NUMBERVALUE(B9)<=13,"Q1",AND(_xlfn.NUMBERVALUE(B9)>13,_xlfn.NUMBERVALUE(B9)<=26),"Q2", AND(_xlfn.NUMBERVALUE(B9)>26,_xlfn.NUMBERVALUE(B9)<=39),"Q3",_xlfn.NUMBERVALUE(B9)>39,"Q4")} -> Q1 | D9: =E8+1 -> 43876 | E9: =D9+6 -> 43882 | F9: 202003 | G9: =SUM(H9:I9) -> 0 | J9: =IFERROR(H9/G9,0) -> 0 | K9: =IFERROR(I9/G9,0) -> 0 | O9: =IFERROR(L9/$G9,0) -> 0 | P9: =IFERROR(M9/$G9,0) -> 0 | Q9: =IFERROR(N9/$G9,0) -> 0 | R9: =Forecast!J4 -> 0 | S9: =Forecast!N4 -> 0 | T9: =IF(OR(RIGHT(F9,2) = "01",G9 = 0),G9,T8+G9) -> 0 | U9: =IF(RIGHT(F9,2)="01",R9,R9+U8) -> 0 | V9: =IF(RIGHT(F9,2)="01",S9,S9+V8) -> 0 | W9: =X9+Y9 -> 0 | X9: ='Channel & Campaign Metrics'!AR8 -> 0 | Y9: ='Channel & Campaign Metrics'!BS8 -> 0 | AB9: ='Glass Metrics'!AC9 -> 0 | AC9: ='Glass Metrics'!I9 -> 0 | AD9: ='Glass Metrics'!N9 -> 0 | AE9: ='Glass Metrics'!S9 -> 0 | AF9: =IFERROR(AE9/AB9,"") | AG9: =IFERROR(AC9/AE9,"") | AH9: =IFERROR(AD9/AC9,"") | AI9: =IFERROR(G9/AB9,"") | AO9: =AJ9 -> 0 | AS9: =AP9 -> 0 | AV9: =SUM(AT9:AU9) -> 0 | BN9: =SUM(BL9:BM9) -> 0
A10: =LEFT(F10,4)+1 -> 2021 | B10: =RIGHT(F10,2) -> 04 | C10: {=_xlfn.IFS(_xlfn.NUMBERVALUE(B10)<=13,"Q1",AND(_xlfn.NUMBERVALUE(B10)>13,_xlfn.NUMBERVALUE(B10)<=26),"Q2", AND(_xlfn.NUMBERVALUE(B10)>26,_xlfn.NUMBERVALUE(B10)<=39),"Q3",_xlfn.NUMBERVALUE(B10)>39,"Q4")} -> Q1 | D10: =E9+1 -> 43883 | E10: =D10+6 -> 43889 | F10: 202004 | G10: =SUM(H10:I10) -> 0 | J10: =IFERROR(H10/G10,0) -> 0 | K10: =IFERROR(I10/G10,0) -> 0 | O10: =IFERROR(L10/$G10,0) -> 0 | P10: =IFERROR(M10/$G10,0) -> 0 | Q10: =IFERROR(N10/$G10,0) -> 0 | R10: =Forecast!J5 -> 0 | S10: =Forecast!N5 -> 0 | T10: =IF(OR(RIGHT(F10,2) = "01",G10 = 0),G10,T9+G10) -> 0 | U10: =IF(RIGHT(F10,2)="01",R10,R10+U9) -> 0 | V10: =IF(RIGHT(F10,2)="01",S10,S10+V9) -> 0 | W10: =X10+Y10 -> 0 | X10: ='Channel & Campaign Metrics'!AR9 -> 0 | Y10: ='Channel & Campaign Metrics'!BS9 -> 0 | AB10: ='Glass Metrics'!AC10 -> 0 | AC10: ='Glass Metrics'!I10 -> 0 | AD10: ='Glass Metrics'!N10 -> 0 | AE10: ='Glass Metrics'!S10 -> 0 | AF10: =IFERROR(AE10/AB10,"") | AG10: =IFERROR(AC10/AE10,"") | AH10: =IFERROR(AD10/AC10,"") | AI10: =IFERROR(G10/AB10,"") | AO10: =AJ10 -> 0 | AS10: =AP10 -> 0 | AV10: =SUM(AT10:AU10) -> 0 | BN10: =SUM(BL10:BM10) -> 0
A11: =LEFT(F11,4)+1 -> 2021 | B11: =RIGHT(F11,2) -> 05 | C11: {=_xlfn.IFS(_xlfn.NUMBERVALUE(B11)<=13,"Q1",AND(_xlfn.NUMBERVALUE(B11)>13,_xlfn.NUMBERVALUE(B11)<=26),"Q2", AND(_xlfn.NUMBERVALUE(B11)>26,_xlfn.NUMBERVALUE(B11)<=39),"Q3",_xlfn.NUMBERVALUE(B11)>39,"Q4")} -> Q1 | D11: =E10+1 -> 43890 | E11: =D11+6 -> 43896 | F11: 202005 | G11: =SUM(H11:I11) -> 0 | J11: =IFERROR(H11/G11,0) -> 0 | K11: =IFERROR(I11/G11,0) -> 0 | O11: =IFERROR(L11/$G11,0) -> 0 | P11: =IFERROR(M11/$G11,0) -> 0 | Q11: =IFERROR(N11/$G11,0) -> 0 | R11: =Forecast!J6 -> 0 | S11: =Forecast!N6 -> 0 | T11: =IF(OR(RIGHT(F11,2) = "01",G11 = 0),G11,T10+G11) -> 0 | U11: =IF(RIGHT(F11,2)="01",R11,R11+U10) -> 0 | V11: =IF(RIGHT(F11,2)="01",S11,S11+V10) -> 0 | W11: =X11+Y11 -> 0 | X11: ='Channel & Campaign Metrics'!AR10 -> 0 | Y11: ='Channel & Campaign Metrics'!BS10 -> 0 | AB11: ='Glass Metrics'!AC11 -> 0 | AC11: ='Glass Metrics'!I11 -> 0 | AD11: ='Glass Metrics'!N11 -> 0 | AE11: ='Glass Metrics'!S11 -> 0 | AF11: =IFERROR(AE11/AB11,"") | AG11: =IFERROR(AC11/AE11,"") | AH11: =IFERROR(AD11/AC11,"") | AI11: =IFERROR(G11/AB11,"") | AO11: =AJ11 -> 0 | AS11: =AP11 -> 0 | AV11: =SUM(AT11:AU11) -> 0 | BN11: =SUM(BL11:BM11) -> 0
A12: =LEFT(F12,4)+1 -> 2021 | B12: =RIGHT(F12,2) -> 06 | C12: {=_xlfn.IFS(_xlfn.NUMBERVALUE(B12)<=13,"Q1",AND(_xlfn.NUMBERVALUE(B12)>13,_xlfn.NUMBERVALUE(B12)<=26),"Q2", AND(_xlfn.NUMBERVALUE(B12)>26,_xlfn.NUMBERVALUE(B12)<=39),"Q3",_xlfn.NUMBERVALUE(B12)>39,"Q4")} -> Q1 | D12: =E11+1 -> 43897 | E12: =D12+6 -> 43903 | F12: 202006 | G12: =SUM(H12:I12) -> 0 | J12: =IFERROR(H12/G12,0) -> 0 | K12: =IFERROR(I12/G12,0) -> 0 | O12: =IFERROR(L12/$G12,0) -> 0 | P12: =IFERROR(M12/$G12,0) -> 0 | Q12: =IFERROR(N12/$G12,0) -> 0 | R12: =Forecast!J7 -> 0 | S12: =Forecast!N7 -> 0 | T12: =IF(OR(RIGHT(F12,2) = "01",G12 = 0),G12,T11+G12) -> 0 | U12: =IF(RIGHT(F12,2)="01",R12,R12+U11) -> 0 | V12: =IF(RIGHT(F12,2)="01",S12,S12+V11) -> 0 | W12: =X12+Y12 -> 0 | X12: ='Channel & Campaign Metrics'!AR11 -> 0 | Y12: ='Channel & Campaign Metrics'!BS11 -> 0 | AB12: ='Glass Metrics'!AC12 -> 0 | AC12: ='Glass Metrics'!I12 -> 0 | AD12: ='Glass Metrics'!N12 -> 0 | AE12: ='Glass Metrics'!S12 -> 0 | AF12: =IFERROR(AE12/AB12,"") | AG12: =IFERROR(AC12/AE12,"") | AH12: =IFERROR(AD12/AC12,"") | AI12: =IFERROR(G12/AB12,"") | AO12: =AJ12 -> 0 | AS12: =AP12 -> 0 | AV12: =SUM(AT12:AU12) -> 0 | BN12: =SUM(BL12:BM12) -> 0
A13: =LEFT(F13,4)+1 -> 2021 | B13: =RIGHT(F13,2) -> 07 | C13: {=_xlfn.IFS(_xlfn.NUMBERVALUE(B13)<=13,"Q1",AND(_xlfn.NUMBERVALUE(B13)>13,_xlfn.NUMBERVALUE(B13)<=26),"Q2", AND(_xlfn.NUMBERVALUE(B13)>26,_xlfn.NUMBERVALUE(B13)<=39),"Q3",_xlfn.NUMBERVALUE(B13)>39,"Q4")} -> Q1 | D13: =E12+1 -> 43904 | E13: =D13+6 -> 43910 | F13: 202007 | G13: =SUM(H13:I13) -> 0 | J13: =IFERROR(H13/G13,0) -> 0 | K13: =IFERROR(I13/G13,0) -> 0 | O13: =IFERROR(L13/$G13,0) -> 0 | P13: =IFERROR(M13/$G13,0) -> 0 | Q13: =IFERROR(N13/$G13,0) -> 0 | R13: =Forecast!J8 -> 0 | S13: =Forecast!N8 -> 0 | T13: =IF(OR(RIGHT(F13,2) = "01",G13 = 0),G13,T12+G13) -> 0 | U13: =IF(RIGHT(F13,2)="01",R13,R13+U12) -> 0 | V13: =IF(RIGHT(F13,2)="01",S13,S13+V12) -> 0 | W13: =X13+Y13 -> 0 | X13: ='Channel & Campaign Metrics'!AR12 -> 0 | Y13: ='Channel & Campaign Metrics'!BS12 -> 0 | AB13: ='Glass Metrics'!AC13 -> 0 | AC13: ='Glass Metrics'!I13 -> 0 | AD13: ='Glass Metrics'!N13 -> 0 | AE13: ='Glass Metrics'!S13 -> 0 | AF13: =IFERROR(AE13/AB13,"") | AG13: =IFERROR(AC13/AE13,"") | AH13: =IFERROR(AD13/AC13,"") | AI13: =IFERROR(G13/AB13,"") | AO13: =AJ13 -> 0 | AS13: =AP13 -> 0 | AV13: =SUM(AT13:AU13) -> 0 | BN13: =SUM(BL13:BM13) -> 0
A14: =LEFT(F14,4)+1 -> 2021 | B14: =RIGHT(F14,2) -> 08 | C14: {=_xlfn.IFS(_xlfn.NUMBERVALUE(B14)<=13,"Q1",AND(_xlfn.NUMBERVALUE(B14)>13,_xlfn.NUMBERVALUE(B14)<=26),"Q2", AND(_xlfn.NUMBERVALUE(B14)>26,_xlfn.NUMBERVALUE(B14)<=39),"Q3",_xlfn.NUMBERVALUE(B14)>39,"Q4")} -> Q1 | D14: =E13+1 -> 43911 | E14: =D14+6 -> 43917 | F14: 202008 | G14: =SUM(H14:I14) -> 0 | J14: =IFERROR(H14/G14,0) -> 0 | K14: =IFERROR(I14/G14,0) -> 0 | O14: =IFERROR(L14/$G14,0) -> 0 | P14: =IFERROR(M14/$G14,0) -> 0 | Q14: =IFERROR(N14/$G14,0) -> 0 | R14: =Forecast!J9 -> 0 | S14: =Forecast!N9 -> 0 | T14: =IF(OR(RIGHT(F14,2) = "01",G14 = 0),G14,T13+G14) -> 0 | U14: =IF(RIGHT(F14,2)="01",R14,R14+U13) -> 0 | V14: =IF(RIGHT(F14,2)="01",S14,S14+V13) -> 0 | W14: =X14+Y14 -> 0 | X14: ='Channel & Campaign Metrics'!AR13 -> 0 | Y14: ='Channel & Campaign Metrics'!BS13 -> 0 | AB14: ='Glass Metrics'!AC14 -> 0 | AC14: ='Glass Metrics'!I14 -> 0 | AD14: ='Glass Metrics'!N14 -> 0 | AE14: ='Glass Metrics'!S14 -> 0 | AF14: =IFERROR(AE14/AB14,"") | AG14: =IFERROR(AC14/AE14,"") | AH14: =IFERROR(AD14/AC14,"") | AI14: =IFERROR(G14/AB14,"") | AO14: =AJ14 -> 0 | AS14: =AP14 -> 0 | AV14: =SUM(AT14:AU14) -> 0 | BN14: =SUM(BL14:BM14) -> 0
A15: =LEFT(F15,4)+1 -> 2021 | B15: =RIGHT(F15,2) -> 09 | C15: {=_xlfn.IFS(_xlfn.NUMBERVALUE(B15)<=13,"Q1",AND(_xlfn.NUMBERVALUE(B15)>13,_xlfn.NUMBERVALUE(B15)<=26),"Q2", AND(_xlfn.NUMBERVALUE(B15)>26,_xlfn.NUMBERVALUE(B15)<=39),"Q3",_xlfn.NUMBERVALUE(B15)>39,"Q4")} -> Q1 | D15: =E14+1 -> 43918 | E15: =D15+6 -> 43924 | F15: 202009 | G15: =SUM(H15:I15) -> 0 | J15: =IFERROR(H15/G15,0) -> 0 | K15: =IFERROR(I15/G15,0) -> 0 | O15: =IFERROR(L15/$G15,0) -> 0 | P15: =IFERROR(M15/$G15,0) -> 0 | Q15: =IFERROR(N15/$G15,0) -> 0 | R15: =Forecast!J10 -> 0 | S15: =Forecast!N10 -> 0 | T15: =IF(OR(RIGHT(F15,2) = "01",G15 = 0),G15,T14+G15) -> 0 | U15: =IF(RIGHT(F15,2)="01",R15,R15+U14) -> 0 | V15: =IF(RIGHT(F15,2)="01",S15,S15+V14) -> 0 | W15: =X15+Y15 -> 0 | X15: ='Channel & Campaign Metrics'!AR14 -> 0 | Y15: ='Channel & Campaign Metrics'!BS14 -> 0 | AB15: ='Glass Metrics'!AC15 -> 0 | AC15: ='Glass Metrics'!I15 -> 0 | AD15: ='Glass Metrics'!N15 -> 0 | AE15: ='Glass Metrics'!S15 -> 0 | AF15: =IFERROR(AE15/AB15,"") | AG15: =IFERROR(AC15/AE15,"") | AH15: =IFERROR(AD15/AC15,"") | AI15: =IFERROR(G15/AB15,"") | AO15: =AJ15 -> 0 | AS15: =AP15 -> 0 | AV15: =SUM(AT15:AU15) -> 0 | BN15: =SUM(BL15:BM15) -> 0
A16: =LEFT(F16,4)+1 -> 2021 | B16: =RIGHT(F16,2) -> 10 | C16: {=_xlfn.IFS(_xlfn.NUMBERVALUE(B16)<=13,"Q1",AND(_xlfn.NUMBERVALUE(B16)>13,_xlfn.NUMBERVALUE(B16)<=26),"Q2", AND(_xlfn.NUMBERVALUE(B16)>26,_xlfn.NUMBERVALUE(B16)<=39),"Q3",_xlfn.NUMBERVALUE(B16)>39,"Q4")} -> Q1 | D16: =E15+1 -> 43925 | E16: =D16+6 -> 43931 | F16: 202010 | G16: =SUM(H16:I16) -> 0 | J16: =IFERROR(H16/G16,0) -> 0 | K16: =IFERROR(I16/G16,0) -> 0 | O16: =IFERROR(L16/$G16,0) -> 0 | P16: =IFERROR(M16/$G16,0) -> 0 | Q16: =IFERROR(N16/$G16,0) -> 0 | R16: =Forecast!J11 -> 0 | S16: =Forecast!N11 -> 0 | T16: =IF(OR(RIGHT(F16,2) = "01",G16 = 0),G16,T15+G16) -> 0 | U16: =IF(RIGHT(F16,2)="01",R16,R16+U15) -> 0 | V16: =IF(RIGHT(F16,2)="01",S16,S16+V15) -> 0 | W16: =X16+Y16 -> 0 | X16: ='Channel & Campaign Metrics'!AR15 -> 0 | Y16: ='Channel & Campaign Metrics'!BS15 -> 0 | AB16: ='Glass Metrics'!AC16 -> 0 | AC16: ='Glass Metrics'!I16 -> 0 | AD16: ='Glass Metrics'!N16 -> 0 | AE16: ='Glass Metrics'!S16 -> 0 | AF16: =IFERROR(AE16/AB16,"") | AG16: =IFERROR(AC16/AE16,"") | AH16: =IFERROR(AD16/AC16,"") | AI16: =IFERROR(G16/AB16,"") | AO16: =AJ16 -> 0 | AS16: =AP16 -> 0 | AV16: =SUM(AT16:AU16) -> 0 | BN16: =SUM(BL16:BM16) -> 0
A17: =LEFT(F17,4)+1 -> 2021 | B17: =RIGHT(F17,2) -> 11 | C17: {=_xlfn.IFS(_xlfn.NUMBERVALUE(B17)<=13,"Q1",AND(_xlfn.NUMBERVALUE(B17)>13,_xlfn.NUMBERVALUE(B17)<=26),"Q2", AND(_xlfn.NUMBERVALUE(B17)>26,_xlfn.NUMBERVALUE(B17)<=39),"Q3",_xlfn.NUMBERVALUE(B17)>39,"Q4")} -> Q1 | D17: =E16+1 -> 43932 | E17: =D17+6 -> 43938 | F17: 202011 | G17: =SUM(H17:I17) -> 0 | J17: =IFERROR(H17/G17,0) -> 0 | K17: =IFERROR(I17/G17,0) -> 0 | O17: =IFERROR(L17/$G17,0) -> 0 | P17: =IFERROR(M17/$G17,0) -> 0 | Q17: =IFERROR(N17/$G17,0) -> 0 | R17: =Forecast!J12 -> 0 | S17: =Forecast!N12 -> 0 | T17: =IF(OR(RIGHT(F17,2) = "01",G17 = 0),G17,T16+G17) -> 0 | U17: =IF(RIGHT(F17,2)="01",R17,R17+U16) -> 0 | V17: =IF(RIGHT(F17,2)="01",S17,S17+V16) -> 0 | W17: =X17+Y17 -> 0 | X17: ='Channel & Campaign Metrics'!AR16 -> 0 | Y17: ='Channel & Campaign Metrics'!BS16 -> 0 | AB17: ='Glass Metrics'!AC17 -> 0 | AC17: ='Glass Metrics'!I17 -> 0 | AD17: ='Glass Metrics'!N17 -> 0 | AE17: ='Glass Metrics'!S17 -> 0 | AF17: =IFERROR(AE17/AB17,"") | AG17: =IFERROR(AC17/AE17,"") | AH17: =IFERROR(AD17/AC17,"") | AI17: =IFERROR(G17/AB17,"") | AO17: =AJ17 -> 0 | AS17: =AP17 -> 0 | AV17: =SUM(AT17:AU17) -> 0 | BN17: =SUM(BL17:BM17) -> 0
A18: =LEFT(F18,4)+1 -> 2021 | B18: =RIGHT(F18,2) -> 12 | C18: {=_xlfn.IFS(_xlfn.NUMBERVALUE(B18)<=13,"Q1",AND(_xlfn.NUMBERVALUE(B18)>13,_xlfn.NUMBERVALUE(B18)<=26),"Q2", AND(_xlfn.NUMBERVALUE(B18)>26,_xlfn.NUMBERVALUE(B18)<=39),"Q3",_xlfn.NUMBERVALUE(B18)>39,"Q4")} -> Q1 | D18: =E17+1 -> 43939 | E18: =D18+6 -> 43945 | F18: 202012 | G18: =SUM(H18:I18) -> 0 | J18: =IFERROR(H18/G18,0) -> 0 | K18: =IFERROR(I18/G18,0) -> 0 | O18: =IFERROR(L18/$G18,0) -> 0 | P18: =IFERROR(M18/$G18,0) -> 0 | Q18: =IFERROR(N18/$G18,0) -> 0 | R18: =Forecast!J13 -> 0 | S18: =Forecast!N13 -> 0 | T18: =IF(OR(RIGHT(F18,2) = "01",G18 = 0),G18,T17+G18) -> 0 | U18: =IF(RIGHT(F18,2)="01",R18,R18+U17) -> 0 | V18: =IF(RIGHT(F18,2)="01",S18,S18+V17) -> 0 | W18: =X18+Y18 -> 0 | X18: ='Channel & Campaign Metrics'!AR17 -> 0 | Y18: ='Channel & Campaign Metrics'!BS17 -> 0 | AB18: ='Glass Metrics'!AC18 -> 0 | AC18: ='Glass Metrics'!I18 -> 0 | AD18: ='Glass Metrics'!N18 -> 0 | AE18: ='Glass Metrics'!S18 -> 0 | AF18: =IFERROR(AE18/AB18,"") | AG18: =IFERROR(AC18/AE18,"") | AH18: =IFERROR(AD18/AC18,"") | AI18: =IFERROR(G18/AB18,"") | AO18: =AJ18 -> 0 | AS18: =AP18 -> 0 | AV18: =SUM(AT18:AU18) -> 0 | BN18: =SUM(BL18:BM18) -> 0
A19: =LEFT(F19,4)+1 -> 2021 | B19: =RIGHT(F19,2) -> 13 | C19: {=_xlfn.IFS(_xlfn.NUMBERVALUE(B19)<=13,"Q1",AND(_xlfn.NUMBERVALUE(B19)>13,_xlfn.NUMBERVALUE(B19)<=26),"Q2", AND(_xlfn.NUMBERVALUE(B19)>26,_xlfn.NUMBERVALUE(B19)<=39),"Q3",_xlfn.NUMBERVALUE(B19)>39,"Q4")} -> Q1 | D19: =E18+1 -> 43946 | E19: =D19+6 -> 43952 | F19: 202013 | G19: =SUM(H19:I19) -> 0 | J19: =IFERROR(H19/G19,0) -> 0 | K19: =IFERROR(I19/G19,0) -> 0 | O19: =IFERROR(L19/$G19,0) -> 0 | P19: =IFERROR(M19/$G19,0) -> 0 | Q19: =IFERROR(N19/$G19,0) -> 0 | R19: =Forecast!J14 -> 0 | S19: =Forecast!N14 -> 0 | T19: =IF(OR(RIGHT(F19,2) = "01",G19 = 0),G19,T18+G19) -> 0 | U19: =IF(RIGHT(F19,2)="01",R19,R19+U18) -> 0 | V19: =IF(RIGHT(F19,2)="01",S19,S19+V18) -> 0 | W19: =X19+Y19 -> 0 | X19: ='Channel & Campaign Metrics'!AR18 -> 0 | Y19: ='Channel & Campaign Metrics'!BS18 -> 0 | AB19: ='Glass Metrics'!AC19 -> 0 | AC19: ='Glass Metrics'!I19 -> 0 | AD19: ='Glass Metrics'!N19 -> 0 | AE19: ='Glass Metrics'!S19 -> 0 | AF19: =IFERROR(AE19/AB19,"") | AG19: =IFERROR(AC19/AE19,"") | AH19: =IFERROR(AD19/AC19,"") | AI19: =IFERROR(G19/AB19,"") | AO19: =AJ19 -> 0 | AS19: =AP19 -> 0 | AV19: =SUM(AT19:AU19) -> 0 | BN19: =SUM(BL19:BM19) -> 0
... A58: =LEFT(F58,4)+1 -> 2021 | B58: =RIGHT(F58,2) -> 52 | C58: {=_xlfn.IFS(_xlfn.NUMBERVALUE(B58)<=13,"Q1",AND(_xlfn.NUMBERVALUE(B58)>13,_xlfn.NUMBERVALUE(B58)<=26),"Q2", AND(_xlfn.NUMBERVALUE(B58)>26,_xlfn.NUMBERVALUE(B58)<=39),"Q3",_xlfn.NUMBERVALUE(B58)>39,"Q4")} -> Q4 | D58: =E57+1 -> 44219 | E58: =D58+6 -> 44225 | F58: 202052 | G58: =SUM(H58:I58) -> 0 | J58: =IFERROR(H58/G58,0) -> 0 | K58: =IFERROR(I58/G58,0) -> 0 | O58: =IFERROR(L58/$G58,0) -> 0 | P58: =IFERROR(M58/$G58,0) -> 0 | Q58: =IFERROR(N58/$G58,0) -> 0 | R58: =Forecast!J53 -> 0 | S58: =Forecast!N53 -> 0 | T58: =IF(OR(RIGHT(F58,2) = "01",G58 = 0),G58,T57+G58) -> 0 | U58: =IF(RIGHT(F58,2)="01",R58,R58+U57) -> 0 | V58: =IF(RIGHT(F58,2)="01",S58,S58+V57) -> 0 | W58: =X58+Y58 -> 0 | X58: ='Channel & Campaign Metrics'!AR57 -> 0 | Y58: ='Channel & Campaign Metrics'!BS57 -> 0 | AB58: ='Glass Metrics'!AC58 -> 0 | AC58: ='Glass Metrics'!I58 -> 0 | AD58: ='Glass Metrics'!N58 -> 0 | AE58: ='Glass Metrics'!S58 -> 0 | AF58: =IFERROR(AE58/AB58,"") | AG58: =IFERROR(AC58/AE58,"") | AH58: =IFERROR(AD58/AC58,"") | AI58: =IFERROR(G58/AB58,"") | AO58: =AJ58 -> 0 | AS58: =AP58 -> 0 | AV58: =SUM(AT58:AU58) -> 0 | BN58: =SUM(BL58:BM58) -> 0
A59: =LEFT(F59,4)+1 -> 2022 | B59: =RIGHT(F59,2) -> 01 | C59: {=_xlfn.IFS(_xlfn.NUMBERVALUE(B59)<=13,"Q1",AND(_xlfn.NUMBERVALUE(B59)>13,_xlfn.NUMBERVALUE(B59)<=26),"Q2", AND(_xlfn.NUMBERVALUE(B59)>26,_xlfn.NUMBERVALUE(B59)<=39),"Q3",_xlfn.NUMBERVALUE(B59)>39,"Q4")} -> Q1 | D59: =E58+1 -> 44226 | E59: =D59+6 -> 44232 | F59: 202101 | G59: =SUM(H59:I59) -> 0 | J59: =IFERROR(H59/G59,0) -> 0 | K59: =IFERROR(I59/G59,0) -> 0 | O59: =IFERROR(L59/$G59,0) -> 0 | P59: =IFERROR(M59/$G59,0) -> 0 | Q59: =IFERROR(N59/$G59,0) -> 0 | R59: =Forecast!J54 -> 0 | S59: =Forecast!N54 -> 0 | T59: =IF(OR(RIGHT(F59,2) = "01",G59 = 0),G59,T58+G59) -> 0 | U59: =IF(RIGHT(F59,2)="01",R59,R59+U58) -> 0 | V59: =IF(RIGHT(F59,2)="01",S59,S59+V58) -> 0 | W59: =X59+Y59 -> 0 | X59: ='Channel & Campaign Metrics'!AR58 -> 0 | Y59: ='Channel & Campaign Metrics'!BS58 -> 0 | AB59: ='Glass Metrics'!AC59 -> 0 | AC59: ='Glass Metrics'!I59 -> 0 | AD59: ='Glass Metrics'!N59 -> 0 | AE59: ='Glass Metrics'!S59 -> 0 | AF59: =IFERROR(AE59/AB59,"") | AG59: =IFERROR(AC59/AE59,"") | AH59: =IFERROR(AD59/AC59,"") | AI59: =IFERROR(G59/AB59,"") | AJ59: =IFERROR(((AK59*AM59)+(AL59*AN59))/(AM59+AN59),"") | AO59: =IFERROR(((AM59*(AK59+0.1))+(AN59*AL59))/(AM59+AN59),"") | AS59: =IFERROR(((AM59*(AQ59+0.15))+(AN59*AR59))/(AM59+AN59),"") | AV59: =SUM(AT59:AU59) -> 0 | AZ59: =H59-(BB59+BD59) -> 0 | BA59: =I59-(BC59+BE59) -> 0 | BF59: =IFERROR(AZ59/L59,"-") -> - | BG59: =IFERROR(BA59/L59,"-") -> - | BH59: =IFERROR(BB59/M59,"-") -> - | BI59: =IFERROR(BC59/M59,"-") -> - | BJ59: =IFERROR(BD59/N59,"-") -> - | BK59: =IFERROR(BE59/N59,"-") -> - | BN59: =SUM(BL59:BM59) -> 0
A60: =LEFT(F60,4)+1 -> 2022 | B60: =RIGHT(F60,2) -> 02 | C60: {=_xlfn.IFS(_xlfn.NUMBERVALUE(B60)<=13,"Q1",AND(_xlfn.NUMBERVALUE(B60)>13,_xlfn.NUMBERVALUE(B60)<=26),"Q2", AND(_xlfn.NUMBERVALUE(B60)>26,_xlfn.NUMBERVALUE(B60)<=39),"Q3",_xlfn.NUMBERVALUE(B60)>39,"Q4")} -> Q1 | D60: =E59+1 -> 44233 | E60: =D60+6 -> 44239 | F60: 202102 | G60: =SUM(H60:I60) -> 0 | J60: =IFERROR(H60/G60,0) -> 0 | K60: =IFERROR(I60/G60,0) -> 0 | O60: =IFERROR(L60/$G60,0) -> 0 | P60: =IFERROR(M60/$G60,0) -> 0 | Q60: =IFERROR(N60/$G60,0) -> 0 | R60: =Forecast!J55 -> 0 | S60: =Forecast!N55 -> 0 | T60: =IF(OR(RIGHT(F60,2) = "01",G60 = 0),G60,T59+G60) -> 0 | U60: =IF(RIGHT(F60,2)="01",R60,R60+U59) -> 0 | V60: =IF(RIGHT(F60,2)="01",S60,S60+V59) -> 0 | W60: =X60+Y60 -> 0 | X60: ='Channel & Campaign Metrics'!AR59 -> 0 | Y60: ='Channel & Campaign Metrics'!BS59 -> 0 | AB60: ='Glass Metrics'!AC60 -> 0 | AC60: ='Glass Metrics'!I60 -> 0 | AD60: ='Glass Metrics'!N60 -> 0 | AE60: ='Glass Metrics'!S60 -> 0 | AF60: =IFERROR(AE60/AB60,"") | AG60: =IFERROR(AC60/AE60,"") | AH60: =IFERROR(AD60/AC60,"") | AI60: =IFERROR(G60/AB60,"") | AJ60: =IFERROR(((AK60*AM60)+(AL60*AN60))/(AM60+AN60),"") | AO60: =IFERROR(((AM60*(AK60+0.1))+(AN60*AL60))/(AM60+AN60),"") | AS60: =IFERROR(((AM60*(AQ60+0.15))+(AN60*AR60))/(AM60+AN60),"") | AV60: =SUM(AT60:AU60) -> 0 | AZ60: =H60-(BB60+BD60) -> 0 | BA60: =I60-(BC60+BE60) -> 0 | BF60: =IFERROR(AZ60/L60,"-") -> - | BG60: =IFERROR(BA60/L60,"-") -> - | BH60: =IFERROR(BB60/M60,"-") -> - | BI60: =IFERROR(BC60/M60,"-") -> - | BJ60: =IFERROR(BD60/N60,"-") -> - | BK60: =IFERROR(BE60/N60,"-") -> - | BN60: =SUM(BL60:BM60) -> 0
A61: =LEFT(F61,4)+1 -> 2022 | B61: =RIGHT(F61,2) -> 03 | C61: {=_xlfn.IFS(_xlfn.NUMBERVALUE(B61)<=13,"Q1",AND(_xlfn.NUMBERVALUE(B61)>13,_xlfn.NUMBERVALUE(B61)<=26),"Q2", AND(_xlfn.NUMBERVALUE(B61)>26,_xlfn.NUMBERVALUE(B61)<=39),"Q3",_xlfn.NUMBERVALUE(B61)>39,"Q4")} -> Q1 | D61: =E60+1 -> 44240 | E61: =D61+6 -> 44246 | F61: 202103 | G61: =SUM(H61:I61) -> 0 | J61: =IFERROR(H61/G61,0) -> 0 | K61: =IFERROR(I61/G61,0) -> 0 | O61: =IFERROR(L61/$G61,0) -> 0 | P61: =IFERROR(M61/$G61,0) -> 0 | Q61: =IFERROR(N61/$G61,0) -> 0 | R61: =Forecast!J56 -> 0 | S61: =Forecast!N56 -> 0 | T61: =IF(OR(RIGHT(F61,2) = "01",G61 = 0),G61,T60+G61) -> 0 | U61: =IF(RIGHT(F61,2)="01",R61,R61+U60) -> 0 | V61: =IF(RIGHT(F61,2)="01",S61,S61+V60) -> 0 | W61: =X61+Y61 -> 0 | X61: ='Channel & Campaign Metrics'!AR60 -> 0 | Y61: ='Channel & Campaign Metrics'!BS60 -> 0 | AB61: ='Glass Metrics'!AC61 -> 0 | AC61: ='Glass Metrics'!I61 -> 0 | AD61: ='Glass Metrics'!N61 -> 0 | AE61: ='Glass Metrics'!S61 -> 0 | AF61: =IFERROR(AE61/AB61,"") | AG61: =IFERROR(AC61/AE61,"") | AH61: =IFERROR(AD61/AC61,"") | AI61: =IFERROR(G61/AB61,"") | AJ61: =IFERROR(((AK61*AM61)+(AL61*AN61))/(AM61+AN61),"") | AO61: =IFERROR(((AM61*(AK61+0.1))+(AN61*AL61))/(AM61+AN61),"") | AS61: =IFERROR(((AM61*(AQ61+0.15))+(AN61*AR61))/(AM61+AN61),"") | AV61: =SUM(AT61:AU61) -> 0 | AZ61: =H61-(BB61+BD61) -> 0 | BA61: =I61-(BC61+BE61) -> 0 | BF61: =IFERROR(AZ61/L61,"-") -> - | BG61: =IFERROR(BA61/L61,"-") -> - | BH61: =IFERROR(BB61/M61,"-") -> - | BI61: =IFERROR(BC61/M61,"-") -> - | BJ61: =IFERROR(BD61/N61,"-") -> - | BK61: =IFERROR(BE61/N61,"-") -> - | BN61: =SUM(BL61:BM61) -> 0
A62: =LEFT(F62,4)+1 -> 2022 | B62: =RIGHT(F62,2) -> 04 | C62: {=_xlfn.IFS(_xlfn.NUMBERVALUE(B62)<=13,"Q1",AND(_xlfn.NUMBERVALUE(B62)>13,_xlfn.NUMBERVALUE(B62)<=26),"Q2", AND(_xlfn.NUMBERVALUE(B62)>26,_xlfn.NUMBERVALUE(B62)<=39),"Q3",_xlfn.NUMBERVALUE(B62)>39,"Q4")} -> Q1 | D62: =E61+1 -> 44247 | E62: =D62+6 -> 44253 | F62: 202104 | G62: =SUM(H62:I62) -> 0 | J62: =IFERROR(H62/G62,0) -> 0 | K62: =IFERROR(I62/G62,0) -> 0 | O62: =IFERROR(L62/$G62,0) -> 0 | P62: =IFERROR(M62/$G62,0) -> 0 | Q62: =IFERROR(N62/$G62,0) -> 0 | R62: =Forecast!J57 -> 0 | S62: =Forecast!N57 -> 0 | T62: =IF(OR(RIGHT(F62,2) = "01",G62 = 0),G62,T61+G62) -> 0 | U62: =IF(RIGHT(F62,2)="01",R62,R62+U61) -> 0 | V62: =IF(RIGHT(F62,2)="01",S62,S62+V61) -> 0 | W62: =X62+Y62 -> 0 | X62: ='Channel & Campaign Metrics'!AR61 -> 0 | Y62: ='Channel & Campaign Metrics'!BS61 -> 0 | AB62: ='Glass Metrics'!AC62 -> 0 | AC62: ='Glass Metrics'!I62 -> 0 | AD62: ='Glass Metrics'!N62 -> 0 | AE62: ='Glass Metrics'!S62 -> 0 | AF62: =IFERROR(AE62/AB62,"") | AG62: =IFERROR(AC62/AE62,"") | AH62: =IFERROR(AD62/AC62,"") | AI62: =IFERROR(G62/AB62,"") | AJ62: =IFERROR(((AK62*AM62)+(AL62*AN62))/(AM62+AN62),"") | AO62: =IFERROR(((AM62*(AK62+0.1))+(AN62*AL62))/(AM62+AN62),"") | AS62: =IFERROR(((AM62*(AQ62+0.15))+(AN62*AR62))/(AM62+AN62),"") | AV62: =SUM(AT62:AU62) -> 0 | AZ62: =H62-(BB62+BD62) -> 0 | BA62: =I62-(BC62+BE62) -> 0 | BF62: =IFERROR(AZ62/L62,"-") -> - | BG62: =IFERROR(BA62/L62,"-") -> - | BH62: =IFERROR(BB62/M62,"-") -> - | BI62: =IFERROR(BC62/M62,"-") -> - | BJ62: =IFERROR(BD62/N62,"-") -> - | BK62: =IFERROR(BE62/N62,"-") -> - | BN62: =SUM(BL62:BM62) -> 0
A63: =LEFT(F63,4)+1 -> 2022 | B63: =RIGHT(F63,2) -> 05 | C63: {=_xlfn.IFS(_xlfn.NUMBERVALUE(B63)<=13,"Q1",AND(_xlfn.NUMBERVALUE(B63)>13,_xlfn.NUMBERVALUE(B63)<=26),"Q2", AND(_xlfn.NUMBERVALUE(B63)>26,_xlfn.NUMBERVALUE(B63)<=39),"Q3",_xlfn.NUMBERVALUE(B63)>39,"Q4")} -> Q1 | D63: =E62+1 -> 44254 | E63: =D63+6 -> 44260 | F63: 202105 | G63: =SUM(H63:I63) -> 0 | J63: =IFERROR(H63/G63,0) -> 0 | K63: =IFERROR(I63/G63,0) -> 0 | O63: =IFERROR(L63/$G63,0) -> 0 | P63: =IFERROR(M63/$G63,0) -> 0 | Q63: =IFERROR(N63/$G63,0) -> 0 | R63: =Forecast!J58 -> 0 | S63: =Forecast!N58 -> 0 | T63: =IF(OR(RIGHT(F63,2) = "01",G63 = 0),G63,T62+G63) -> 0 | U63: =IF(RIGHT(F63,2)="01",R63,R63+U62) -> 0 | V63: =IF(RIGHT(F63,2)="01",S63,S63+V62) -> 0 | W63: =X63+Y63 -> 0 | X63: ='Channel & Campaign Metrics'!AR62 -> 0 | Y63: ='Channel & Campaign Metrics'!BS62 -> 0 | AB63: ='Glass Metrics'!AC63 -> 0 | AC63: ='Glass Metrics'!I63 -> 0 | AD63: ='Glass Metrics'!N63 -> 0 | AE63: ='Glass Metrics'!S63 -> 0 | AF63: =IFERROR(AE63/AB63,"") | AG63: =IFERROR(AC63/AE63,"") | AH63: =IFERROR(AD63/AC63,"") | AI63: =IFERROR(G63/AB63,"") | AJ63: =IFERROR(((AK63*AM63)+(AL63*AN63))/(AM63+AN63),"") | AO63: =IFERROR(((AM63*(AK63+0.1))+(AN63*AL63))/(AM63+AN63),"") | AS63: =IFERROR(((AM63*(AQ63+0.15))+(AN63*AR63))/(AM63+AN63),"") | AV63: =SUM(AT63:AU63) -> 0 | AZ63: =H63-(BB63+BD63) -> 0 | BA63: =I63-(BC63+BE63) -> 0 | BF63: =IFERROR(AZ63/L63,"-") -> - | BG63: =IFERROR(BA63/L63,"-") -> - | BH63: =IFERROR(BB63/M63,"-") -> - | BI63: =IFERROR(BC63/M63,"-") -> - | BJ63: =IFERROR(BD63/N63,"-") -> - | BK63: =IFERROR(BE63/N63,"-") -> - | BN63: =SUM(BL63:BM63) -> 0
A64: =LEFT(F64,4)+1 -> 2022 | B64: =RIGHT(F64,2) -> 06 | C64: {=_xlfn.IFS(_xlfn.NUMBERVALUE(B64)<=13,"Q1",AND(_xlfn.NUMBERVALUE(B64)>13,_xlfn.NUMBERVALUE(B64)<=26),"Q2", AND(_xlfn.NUMBERVALUE(B64)>26,_xlfn.NUMBERVALUE(B64)<=39),"Q3",_xlfn.NUMBERVALUE(B64)>39,"Q4")} -> Q1 | D64: =E63+1 -> 44261 | E64: =D64+6 -> 44267 | F64: 202106 | G64: =SUM(H64:I64) -> 0 | J64: =IFERROR(H64/G64,0) -> 0 | K64: =IFERROR(I64/G64,0) -> 0 | O64: =IFERROR(L64/$G64,0) -> 0 | P64: =IFERROR(M64/$G64,0) -> 0 | Q64: =IFERROR(N64/$G64,0) -> 0 | R64: =Forecast!J59 -> 0 | S64: =Forecast!N59 -> 0 | T64: =IF(OR(RIGHT(F64,2) = "01",G64 = 0),G64,T63+G64) -> 0 | U64: =IF(RIGHT(F64,2)="01",R64,R64+U63) -> 0 | V64: =IF(RIGHT(F64,2)="01",S64,S64+V63) -> 0 | W64: =X64+Y64 -> 0 | X64: ='Channel & Campaign Metrics'!AR63 -> 0 | Y64: ='Channel & Campaign Metrics'!BS63 -> 0 | AB64: ='Glass Metrics'!AC64 -> 0 | AC64: ='Glass Metrics'!I64 -> 0 | AD64: ='Glass Metrics'!N64 -> 0 | AE64: ='Glass Metrics'!S64 -> 0 | AF64: =IFERROR(AE64/AB64,"") | AG64: =IFERROR(AC64/AE64,"") | AH64: =IFERROR(AD64/AC64,"") | AI64: =IFERROR(G64/AB64,"") | AJ64: =IFERROR(((AK64*AM64)+(AL64*AN64))/(AM64+AN64),"") | AO64: =IFERROR(((AM64*(AK64+0.1))+(AN64*AL64))/(AM64+AN64),"") | AS64: =IFERROR(((AM64*(AQ64+0.15))+(AN64*AR64))/(AM64+AN64),"") | AV64: =SUM(AT64:AU64) -> 0 | AZ64: =H64-(BB64+BD64) -> 0 | BA64: =I64-(BC64+BE64) -> 0 | BF64: =IFERROR(AZ64/L64,"-") -> - | BG64: =IFERROR(BA64/L64,"-") -> - | BH64: =IFERROR(BB64/M64,"-") -> - | BI64: =IFERROR(BC64/M64,"-") -> - | BJ64: =IFERROR(BD64/N64,"-") -> - | BK64: =IFERROR(BE64/N64,"-") -> - | BN64: =SUM(BL64:BM64) -> 0
A65: =LEFT(F65,4)+1 -> 2022 | B65: =RIGHT(F65,2) -> 07 | C65: {=_xlfn.IFS(_xlfn.NUMBERVALUE(B65)<=13,"Q1",AND(_xlfn.NUMBERVALUE(B65)>13,_xlfn.NUMBERVALUE(B65)<=26),"Q2", AND(_xlfn.NUMBERVALUE(B65)>26,_xlfn.NUMBERVALUE(B65)<=39),"Q3",_xlfn.NUMBERVALUE(B65)>39,"Q4")} -> Q1 | D65: =E64+1 -> 44268 | E65: =D65+6 -> 44274 | F65: 202107 | G65: =SUM(H65:I65) -> 0 | J65: =IFERROR(H65/G65,0) -> 0 | K65: =IFERROR(I65/G65,0) -> 0 | O65: =IFERROR(L65/$G65,0) -> 0 | P65: =IFERROR(M65/$G65,0) -> 0 | Q65: =IFERROR(N65/$G65,0) -> 0 | R65: =Forecast!J60 -> 0 | S65: =Forecast!N60 -> 0 | T65: =IF(OR(RIGHT(F65,2) = "01",G65 = 0),G65,T64+G65) -> 0 | U65: =IF(RIGHT(F65,2)="01",R65,R65+U64) -> 0 | V65: =IF(RIGHT(F65,2)="01",S65,S65+V64) -> 0 | W65: =X65+Y65 -> 0 | X65: ='Channel & Campaign Metrics'!AR64 -> 0 | Y65: ='Channel & Campaign Metrics'!BS64 -> 0 | AB65: ='Glass Metrics'!AC65 -> 0 | AC65: ='Glass Metrics'!I65 -> 0 | AD65: ='Glass Metrics'!N65 -> 0 | AE65: ='Glass Metrics'!S65 -> 0 | AF65: =IFERROR(AE65/AB65,"") | AG65: =IFERROR(AC65/AE65,"") | AH65: =IFERROR(AD65/AC65,"") | AI65: =IFERROR(G65/AB65,"") | AJ65: =IFERROR(((AK65*AM65)+(AL65*AN65))/(AM65+AN65),"") | AO65: =IFERROR(((AM65*(AK65+0.1))+(AN65*AL65))/(AM65+AN65),"") | AS65: =IFERROR(((AM65*(AQ65+0.15))+(AN65*AR65))/(AM65+AN65),"") | AV65: =SUM(AT65:AU65) -> 0 | AZ65: =H65-(BB65+BD65) -> 0 | BA65: =I65-(BC65+BE65) -> 0 | BF65: =IFERROR(AZ65/L65,"-") -> - | BG65: =IFERROR(BA65/L65,"-") -> - | BH65: =IFERROR(BB65/M65,"-") -> - | BI65: =IFERROR(BC65/M65,"-") -> - | BJ65: =IFERROR(BD65/N65,"-") -> - | BK65: =IFERROR(BE65/N65,"-") -> - | BN65: =SUM(BL65:BM65) -> 0
